2018-06-29 11:14:13,438 [django.request:93] [base:get_response] [WARNING]- Not Found: /
2018-06-29 11:14:32,678 [HttpRunnerManager:45] [views:login] [INFO]- yinquanwang 登录成功
2018-06-29 11:14:33,058 [django.request:93] [base:get_response] [WARNING]- Not Found: /static/assets/js/commons.js
2018-06-29 11:14:33,499 [django.request:93] [base:get_response] [WARNING]- Not Found: /static/assets/js/commons.js
2018-06-29 11:14:58,797 [HttpRunnerManager:45] [views:login] [INFO]- yinquanwang 登录成功
2018-06-29 11:48:11,403 [HttpRunnerManager:151] [operation:add_case_data] [INFO]- 的用例添加成功: {'test': {'request': {'method': 'POST', 'url': ''}, 'name': '的'}}
2018-06-29 11:48:48,076 [HttpRunnerManager:45] [views:login] [INFO]- yinquanwang 登录成功
2018-07-02 13:34:18,047 [django.request:93] [base:get_response] [WARNING]- Not Found: /static/assets/css/css-index.css
2018-07-02 13:34:18,057 [django.request:93] [base:get_response] [WARNING]- Not Found: /static/assets/img/logo.png
2018-07-02 13:34:18,268 [django.request:93] [base:get_response] [WARNING]- Not Found: /static/assets/js/custom.js
2018-07-02 13:34:18,270 [django.request:93] [base:get_response] [WARNING]- Not Found: /static/assets/js/jquery.sticky.js
2018-07-02 13:34:18,276 [django.request:93] [base:get_response] [WARNING]- Not Found: /static/assets/js/wow.min.js
2018-07-02 13:34:18,278 [django.request:93] [base:get_response] [WARNING]- Not Found: /static/assets/js/owl.carousel.min.js
2018-07-02 13:34:18,296 [django.request:93] [base:get_response] [WARNING]- Not Found: /static/assets/img/bg.jpg
2018-07-02 13:34:18,299 [django.request:93] [base:get_response] [WARNING]- Not Found: /static/assets/img/loading.GIF
2018-07-02 13:34:18,352 [django.request:93] [base:get_response] [WARNING]- Not Found: /static/assets/js/custom.js
2018-07-02 13:34:18,364 [django.request:93] [base:get_response] [WARNING]- Not Found: /static/assets/js/jquery.sticky.js
2018-07-02 13:34:18,370 [django.request:93] [base:get_response] [WARNING]- Not Found: /static/assets/js/wow.min.js
2018-07-02 13:34:18,383 [django.request:93] [base:get_response] [WARNING]- Not Found: /static/assets/js/owl.carousel.min.js
2018-07-02 13:34:18,578 [django.request:93] [base:get_response] [WARNING]- Not Found: /static/assets/img/favicon.ico
2018-07-02 13:34:21,442 [django.request:93] [base:get_response] [WARNING]- Not Found: /static/assets/css/css-index.css
2018-07-02 13:34:21,445 [django.request:93] [base:get_response] [WARNING]- Not Found: /static/assets/js/custom.js
2018-07-02 13:34:21,449 [django.request:93] [base:get_response] [WARNING]- Not Found: /static/assets/img/logo.png
2018-07-02 13:34:21,484 [django.request:93] [base:get_response] [WARNING]- Not Found: /static/assets/js/jquery.sticky.js
2018-07-02 13:34:21,487 [django.request:93] [base:get_response] [WARNING]- Not Found: /static/assets/js/wow.min.js
2018-07-02 13:34:21,492 [django.request:93] [base:get_response] [WARNING]- Not Found: /static/assets/js/owl.carousel.min.js
2018-07-02 13:34:21,508 [django.request:93] [base:get_response] [WARNING]- Not Found: /static/assets/js/custom.js
2018-07-02 13:34:21,516 [django.request:93] [base:get_response] [WARNING]- Not Found: /static/assets/img/bg.jpg
2018-07-02 13:34:21,519 [django.request:93] [base:get_response] [WARNING]- Not Found: /static/assets/img/loading.GIF
2018-07-02 13:34:21,531 [django.request:93] [base:get_response] [WARNING]- Not Found: /static/assets/js/jquery.sticky.js
2018-07-02 13:34:21,540 [django.request:93] [base:get_response] [WARNING]- Not Found: /static/assets/js/wow.min.js
2018-07-02 13:34:21,545 [django.request:93] [base:get_response] [WARNING]- Not Found: /static/assets/js/owl.carousel.min.js
2018-07-02 13:34:22,424 [django.request:93] [base:get_response] [WARNING]- Not Found: /static/assets/css/css-index.css
2018-07-02 13:34:22,426 [django.request:93] [base:get_response] [WARNING]- Not Found: /static/assets/img/logo.png
2018-07-02 13:34:22,429 [django.request:93] [base:get_response] [WARNING]- Not Found: /static/assets/js/custom.js
2018-07-02 13:34:22,465 [django.request:93] [base:get_response] [WARNING]- Not Found: /static/assets/js/jquery.sticky.js
2018-07-02 13:34:22,466 [django.request:93] [base:get_response] [WARNING]- Not Found: /static/assets/js/wow.min.js
2018-07-02 13:34:22,468 [django.request:93] [base:get_response] [WARNING]- Not Found: /static/assets/js/owl.carousel.min.js
2018-07-02 13:34:22,480 [django.request:93] [base:get_response] [WARNING]- Not Found: /static/assets/js/custom.js
2018-07-02 13:34:22,483 [django.request:93] [base:get_response] [WARNING]- Not Found: /static/assets/img/bg.jpg
2018-07-02 13:34:22,490 [django.request:93] [base:get_response] [WARNING]- Not Found: /static/assets/img/loading.GIF
2018-07-02 13:34:22,498 [django.request:93] [base:get_response] [WARNING]- Not Found: /static/assets/js/jquery.sticky.js
2018-07-02 13:34:22,506 [django.request:93] [base:get_response] [WARNING]- Not Found: /static/assets/js/wow.min.js
2018-07-02 13:34:22,509 [django.request:93] [base:get_response] [WARNING]- Not Found: /static/assets/js/owl.carousel.min.js
2018-07-02 13:35:30,488 [HttpRunnerManager:45] [views:login] [INFO]- yinquanwang 登录成功
2018-07-02 13:48:28,352 [HttpRunnerManager:45] [views:login] [INFO]- yinquanwang 登录成功
2018-07-02 13:53:41,984 [django.request:118] [exception:handle_uncaught_exception] [ERROR]- Internal Server Error: /api/test_list/1/
Traceback (most recent call last):
  File "E:\Python35\lib\site-packages\django\core\handlers\exception.py", line 35, in inner
    response = get_response(request)
  File "E:\Python35\lib\site-packages\django\core\handlers\base.py", line 128, in _get_response
    response = self.process_exception_by_middleware(e, request)
  File "E:\Python35\lib\site-packages\django\core\handlers\base.py", line 126, in _get_response
    response = wrapped_callback(request, *callback_args, **callback_kwargs)
  File "D:/HttpRunnerManager\HttpRunnerManager\activator.py", line 15, in process
    result = fun(request, index) if index else fun(request)
  File "D:/HttpRunnerManager\ApiManager\views.py", line 379, in test_list
    filter_query = set_filter_session(request)
  File "D:/HttpRunnerManager\ApiManager\utils\common.py", line 439, in set_filter_session
    'belong_project': request.session['project'],
  File "E:\Python35\lib\site-packages\django\contrib\sessions\backends\base.py", line 55, in __getitem__
    return self._session[key]
KeyError: 'project'
2018-07-02 13:53:49,147 [django.request:118] [exception:handle_uncaught_exception] [ERROR]- Internal Server Error: /api/test_list/1/
Traceback (most recent call last):
  File "E:\Python35\lib\site-packages\django\core\handlers\exception.py", line 35, in inner
    response = get_response(request)
  File "E:\Python35\lib\site-packages\django\core\handlers\base.py", line 128, in _get_response
    response = self.process_exception_by_middleware(e, request)
  File "E:\Python35\lib\site-packages\django\core\handlers\base.py", line 126, in _get_response
    response = wrapped_callback(request, *callback_args, **callback_kwargs)
  File "D:/HttpRunnerManager\HttpRunnerManager\activator.py", line 15, in process
    result = fun(request, index) if index else fun(request)
  File "D:/HttpRunnerManager\ApiManager\views.py", line 379, in test_list
    filter_query = set_filter_session(request)
  File "D:/HttpRunnerManager\ApiManager\utils\common.py", line 439, in set_filter_session
    'belong_project': request.session['project'],
  File "E:\Python35\lib\site-packages\django\contrib\sessions\backends\base.py", line 55, in __getitem__
    return self._session[key]
KeyError: 'project'
2018-07-02 13:54:04,117 [HttpRunnerManager:78] [views:log_out] [INFO]- yinquanwang退出
2018-07-02 13:54:07,459 [HttpRunnerManager:45] [views:login] [INFO]- yinquanwang 登录成功
2018-07-02 13:57:09,661 [HttpRunnerManager:78] [views:log_out] [INFO]- yinquanwang退出
2018-07-02 13:57:11,824 [HttpRunnerManager:45] [views:login] [INFO]- yinquanwang 登录成功
2018-07-02 14:04:39,039 [HttpRunnerManager:78] [views:log_out] [INFO]- yinquanwang退出
2018-07-02 14:04:44,830 [HttpRunnerManager:45] [views:login] [INFO]- yinquanwang 登录成功
2018-07-02 14:04:54,650 [django.request:118] [exception:handle_uncaught_exception] [ERROR]- Internal Server Error: /api/test_list/1/
Traceback (most recent call last):
  File "E:\Python35\lib\site-packages\django\core\handlers\exception.py", line 35, in inner
    response = get_response(request)
  File "E:\Python35\lib\site-packages\django\core\handlers\base.py", line 128, in _get_response
    response = self.process_exception_by_middleware(e, request)
  File "E:\Python35\lib\site-packages\django\core\handlers\base.py", line 126, in _get_response
    response = wrapped_callback(request, *callback_args, **callback_kwargs)
  File "D:\HttpRunnerManager\HttpRunnerManager\activator.py", line 15, in process
    result = fun(request, index) if index else fun(request)
  File "D:\HttpRunnerManager\ApiManager\views.py", line 379, in test_list
    filter_query = set_filter_session(request)
  File "D:\HttpRunnerManager\ApiManager\utils\common.py", line 432, in set_filter_session
    request.session['module'] = ModuleInfo.objects.get(id=request.POST.get('module')).module_name
  File "E:\Python35\lib\site-packages\django\db\models\manager.py", line 82, in manager_method
    return getattr(self.get_queryset(), name)(*args, **kwargs)
  File "E:\Python35\lib\site-packages\django\db\models\query.py", line 394, in get
    clone = self.filter(*args, **kwargs)
  File "E:\Python35\lib\site-packages\django\db\models\query.py", line 836, in filter
    return self._filter_or_exclude(False, *args, **kwargs)
  File "E:\Python35\lib\site-packages\django\db\models\query.py", line 854, in _filter_or_exclude
    clone.query.add_q(Q(*args, **kwargs))
  File "E:\Python35\lib\site-packages\django\db\models\sql\query.py", line 1253, in add_q
    clause, _ = self._add_q(q_object, self.used_aliases)
  File "E:\Python35\lib\site-packages\django\db\models\sql\query.py", line 1277, in _add_q
    split_subq=split_subq,
  File "E:\Python35\lib\site-packages\django\db\models\sql\query.py", line 1215, in build_filter
    condition = self.build_lookup(lookups, col, value)
  File "E:\Python35\lib\site-packages\django\db\models\sql\query.py", line 1085, in build_lookup
    lookup = lookup_class(lhs, rhs)
  File "E:\Python35\lib\site-packages\django\db\models\lookups.py", line 18, in __init__
    self.rhs = self.get_prep_lookup()
  File "E:\Python35\lib\site-packages\django\db\models\lookups.py", line 68, in get_prep_lookup
    return self.lhs.output_field.get_prep_value(self.rhs)
  File "E:\Python35\lib\site-packages\django\db\models\fields\__init__.py", line 947, in get_prep_value
    return int(value)
ValueError: invalid literal for int() with base 10: ''
2018-07-02 14:06:02,565 [django.request:118] [exception:handle_uncaught_exception] [ERROR]- Internal Server Error: /api/config_list/1/
Traceback (most recent call last):
  File "E:\Python35\lib\site-packages\django\core\handlers\exception.py", line 35, in inner
    response = get_response(request)
  File "E:\Python35\lib\site-packages\django\core\handlers\base.py", line 128, in _get_response
    response = self.process_exception_by_middleware(e, request)
  File "E:\Python35\lib\site-packages\django\core\handlers\base.py", line 126, in _get_response
    response = wrapped_callback(request, *callback_args, **callback_kwargs)
  File "D:\HttpRunnerManager\HttpRunnerManager\activator.py", line 15, in process
    result = fun(request, index) if index else fun(request)
  File "D:\HttpRunnerManager\ApiManager\views.py", line 413, in config_list
    filter_query = set_filter_session(request)
  File "D:\HttpRunnerManager\ApiManager\utils\common.py", line 432, in set_filter_session
    request.session['module'] = ModuleInfo.objects.get(id=request.POST.get('module')).module_name
  File "E:\Python35\lib\site-packages\django\db\models\manager.py", line 82, in manager_method
    return getattr(self.get_queryset(), name)(*args, **kwargs)
  File "E:\Python35\lib\site-packages\django\db\models\query.py", line 394, in get
    clone = self.filter(*args, **kwargs)
  File "E:\Python35\lib\site-packages\django\db\models\query.py", line 836, in filter
    return self._filter_or_exclude(False, *args, **kwargs)
  File "E:\Python35\lib\site-packages\django\db\models\query.py", line 854, in _filter_or_exclude
    clone.query.add_q(Q(*args, **kwargs))
  File "E:\Python35\lib\site-packages\django\db\models\sql\query.py", line 1253, in add_q
    clause, _ = self._add_q(q_object, self.used_aliases)
  File "E:\Python35\lib\site-packages\django\db\models\sql\query.py", line 1277, in _add_q
    split_subq=split_subq,
  File "E:\Python35\lib\site-packages\django\db\models\sql\query.py", line 1215, in build_filter
    condition = self.build_lookup(lookups, col, value)
  File "E:\Python35\lib\site-packages\django\db\models\sql\query.py", line 1085, in build_lookup
    lookup = lookup_class(lhs, rhs)
  File "E:\Python35\lib\site-packages\django\db\models\lookups.py", line 18, in __init__
    self.rhs = self.get_prep_lookup()
  File "E:\Python35\lib\site-packages\django\db\models\lookups.py", line 68, in get_prep_lookup
    return self.lhs.output_field.get_prep_value(self.rhs)
  File "E:\Python35\lib\site-packages\django\db\models\fields\__init__.py", line 947, in get_prep_value
    return int(value)
ValueError: invalid literal for int() with base 10: ''
2018-07-02 14:24:14,328 [HttpRunnerManager:78] [views:log_out] [INFO]- yinquanwang退出
2018-07-02 14:24:16,921 [HttpRunnerManager:45] [views:login] [INFO]- yinquanwang 登录成功
2018-07-02 14:27:17,963 [django.request:118] [exception:handle_uncaught_exception] [ERROR]- Internal Server Error: /api/project_list/1/
Traceback (most recent call last):
  File "E:\Python35\lib\site-packages\django\template\base.py", line 475, in parse
    compile_func = self.tags[command]
KeyError: 'endif'

During handling of the above exception, another exception occurred:

Traceback (most recent call last):
  File "E:\Python35\lib\site-packages\django\core\handlers\exception.py", line 35, in inner
    response = get_response(request)
  File "E:\Python35\lib\site-packages\django\core\handlers\base.py", line 128, in _get_response
    response = self.process_exception_by_middleware(e, request)
  File "E:\Python35\lib\site-packages\django\core\handlers\base.py", line 126, in _get_response
    response = wrapped_callback(request, *callback_args, **callback_kwargs)
  File "D:\HttpRunnerManager\HttpRunnerManager\activator.py", line 15, in process
    result = fun(request, index) if index else fun(request)
  File "D:\HttpRunnerManager\ApiManager\views.py", line 323, in project_list
    return render_to_response('project_list.html', manage_info)
  File "E:\Python35\lib\site-packages\django\shortcuts.py", line 27, in render_to_response
    content = loader.render_to_string(template_name, context, using=using)
  File "E:\Python35\lib\site-packages\django\template\loader.py", line 61, in render_to_string
    template = get_template(template_name, using=using)
  File "E:\Python35\lib\site-packages\django\template\loader.py", line 15, in get_template
    return engine.get_template(template_name)
  File "E:\Python35\lib\site-packages\django\template\backends\django.py", line 34, in get_template
    return Template(self.engine.get_template(template_name), self)
  File "E:\Python35\lib\site-packages\django\template\engine.py", line 144, in get_template
    template, origin = self.find_template(template_name)
  File "E:\Python35\lib\site-packages\django\template\engine.py", line 126, in find_template
    template = loader.get_template(name, skip=skip)
  File "E:\Python35\lib\site-packages\django\template\loaders\base.py", line 30, in get_template
    contents, origin, origin.template_name, self.engine,
  File "E:\Python35\lib\site-packages\django\template\base.py", line 160, in __init__
    self.nodelist = self.compile_nodelist()
  File "E:\Python35\lib\site-packages\django\template\base.py", line 198, in compile_nodelist
    return parser.parse()
  File "E:\Python35\lib\site-packages\django\template\base.py", line 483, in parse
    raise self.error(token, e)
  File "E:\Python35\lib\site-packages\django\template\base.py", line 481, in parse
    compiled_result = compile_func(self, token)
  File "E:\Python35\lib\site-packages\django\template\loader_tags.py", line 290, in do_extends
    nodelist = parser.parse()
  File "E:\Python35\lib\site-packages\django\template\base.py", line 483, in parse
    raise self.error(token, e)
  File "E:\Python35\lib\site-packages\django\template\base.py", line 481, in parse
    compiled_result = compile_func(self, token)
  File "E:\Python35\lib\site-packages\django\template\loader_tags.py", line 233, in do_block
    nodelist = parser.parse(('endblock',))
  File "E:\Python35\lib\site-packages\django\template\base.py", line 477, in parse
    self.invalid_block_tag(token, command, parse_until)
  File "E:\Python35\lib\site-packages\django\template\base.py", line 533, in invalid_block_tag
    get_text_list(["'%s'" % p for p in parse_until], 'or'),
django.template.exceptions.TemplateSyntaxError: Invalid block tag on line 176: 'endif', expected 'endblock'. Did you forget to register or load this tag?
2018-07-02 14:27:44,949 [django.request:118] [exception:handle_uncaught_exception] [ERROR]- Internal Server Error: /api/project_list/1/
Traceback (most recent call last):
  File "E:\Python35\lib\site-packages\django\template\base.py", line 475, in parse
    compile_func = self.tags[command]
KeyError: 'endif'

During handling of the above exception, another exception occurred:

Traceback (most recent call last):
  File "E:\Python35\lib\site-packages\django\core\handlers\exception.py", line 35, in inner
    response = get_response(request)
  File "E:\Python35\lib\site-packages\django\core\handlers\base.py", line 128, in _get_response
    response = self.process_exception_by_middleware(e, request)
  File "E:\Python35\lib\site-packages\django\core\handlers\base.py", line 126, in _get_response
    response = wrapped_callback(request, *callback_args, **callback_kwargs)
  File "D:\HttpRunnerManager\HttpRunnerManager\activator.py", line 15, in process
    result = fun(request, index) if index else fun(request)
  File "D:\HttpRunnerManager\ApiManager\views.py", line 323, in project_list
    return render_to_response('project_list.html', manage_info)
  File "E:\Python35\lib\site-packages\django\shortcuts.py", line 27, in render_to_response
    content = loader.render_to_string(template_name, context, using=using)
  File "E:\Python35\lib\site-packages\django\template\loader.py", line 61, in render_to_string
    template = get_template(template_name, using=using)
  File "E:\Python35\lib\site-packages\django\template\loader.py", line 15, in get_template
    return engine.get_template(template_name)
  File "E:\Python35\lib\site-packages\django\template\backends\django.py", line 34, in get_template
    return Template(self.engine.get_template(template_name), self)
  File "E:\Python35\lib\site-packages\django\template\engine.py", line 144, in get_template
    template, origin = self.find_template(template_name)
  File "E:\Python35\lib\site-packages\django\template\engine.py", line 126, in find_template
    template = loader.get_template(name, skip=skip)
  File "E:\Python35\lib\site-packages\django\template\loaders\base.py", line 30, in get_template
    contents, origin, origin.template_name, self.engine,
  File "E:\Python35\lib\site-packages\django\template\base.py", line 160, in __init__
    self.nodelist = self.compile_nodelist()
  File "E:\Python35\lib\site-packages\django\template\base.py", line 198, in compile_nodelist
    return parser.parse()
  File "E:\Python35\lib\site-packages\django\template\base.py", line 483, in parse
    raise self.error(token, e)
  File "E:\Python35\lib\site-packages\django\template\base.py", line 481, in parse
    compiled_result = compile_func(self, token)
  File "E:\Python35\lib\site-packages\django\template\loader_tags.py", line 290, in do_extends
    nodelist = parser.parse()
  File "E:\Python35\lib\site-packages\django\template\base.py", line 483, in parse
    raise self.error(token, e)
  File "E:\Python35\lib\site-packages\django\template\base.py", line 481, in parse
    compiled_result = compile_func(self, token)
  File "E:\Python35\lib\site-packages\django\template\loader_tags.py", line 233, in do_block
    nodelist = parser.parse(('endblock',))
  File "E:\Python35\lib\site-packages\django\template\base.py", line 477, in parse
    self.invalid_block_tag(token, command, parse_until)
  File "E:\Python35\lib\site-packages\django\template\base.py", line 533, in invalid_block_tag
    get_text_list(["'%s'" % p for p in parse_until], 'or'),
django.template.exceptions.TemplateSyntaxError: Invalid block tag on line 176: 'endif', expected 'endblock'. Did you forget to register or load this tag?
2018-07-02 14:27:47,983 [django.request:118] [exception:handle_uncaught_exception] [ERROR]- Internal Server Error: /api/project_list/1/
Traceback (most recent call last):
  File "E:\Python35\lib\site-packages\django\template\base.py", line 475, in parse
    compile_func = self.tags[command]
KeyError: 'endif'

During handling of the above exception, another exception occurred:

Traceback (most recent call last):
  File "E:\Python35\lib\site-packages\django\core\handlers\exception.py", line 35, in inner
    response = get_response(request)
  File "E:\Python35\lib\site-packages\django\core\handlers\base.py", line 128, in _get_response
    response = self.process_exception_by_middleware(e, request)
  File "E:\Python35\lib\site-packages\django\core\handlers\base.py", line 126, in _get_response
    response = wrapped_callback(request, *callback_args, **callback_kwargs)
  File "D:\HttpRunnerManager\HttpRunnerManager\activator.py", line 15, in process
    result = fun(request, index) if index else fun(request)
  File "D:\HttpRunnerManager\ApiManager\views.py", line 323, in project_list
    return render_to_response('project_list.html', manage_info)
  File "E:\Python35\lib\site-packages\django\shortcuts.py", line 27, in render_to_response
    content = loader.render_to_string(template_name, context, using=using)
  File "E:\Python35\lib\site-packages\django\template\loader.py", line 61, in render_to_string
    template = get_template(template_name, using=using)
  File "E:\Python35\lib\site-packages\django\template\loader.py", line 15, in get_template
    return engine.get_template(template_name)
  File "E:\Python35\lib\site-packages\django\template\backends\django.py", line 34, in get_template
    return Template(self.engine.get_template(template_name), self)
  File "E:\Python35\lib\site-packages\django\template\engine.py", line 144, in get_template
    template, origin = self.find_template(template_name)
  File "E:\Python35\lib\site-packages\django\template\engine.py", line 126, in find_template
    template = loader.get_template(name, skip=skip)
  File "E:\Python35\lib\site-packages\django\template\loaders\base.py", line 30, in get_template
    contents, origin, origin.template_name, self.engine,
  File "E:\Python35\lib\site-packages\django\template\base.py", line 160, in __init__
    self.nodelist = self.compile_nodelist()
  File "E:\Python35\lib\site-packages\django\template\base.py", line 198, in compile_nodelist
    return parser.parse()
  File "E:\Python35\lib\site-packages\django\template\base.py", line 483, in parse
    raise self.error(token, e)
  File "E:\Python35\lib\site-packages\django\template\base.py", line 481, in parse
    compiled_result = compile_func(self, token)
  File "E:\Python35\lib\site-packages\django\template\loader_tags.py", line 290, in do_extends
    nodelist = parser.parse()
  File "E:\Python35\lib\site-packages\django\template\base.py", line 483, in parse
    raise self.error(token, e)
  File "E:\Python35\lib\site-packages\django\template\base.py", line 481, in parse
    compiled_result = compile_func(self, token)
  File "E:\Python35\lib\site-packages\django\template\loader_tags.py", line 233, in do_block
    nodelist = parser.parse(('endblock',))
  File "E:\Python35\lib\site-packages\django\template\base.py", line 477, in parse
    self.invalid_block_tag(token, command, parse_until)
  File "E:\Python35\lib\site-packages\django\template\base.py", line 533, in invalid_block_tag
    get_text_list(["'%s'" % p for p in parse_until], 'or'),
django.template.exceptions.TemplateSyntaxError: Invalid block tag on line 176: 'endif', expected 'endblock'. Did you forget to register or load this tag?
2018-07-02 14:28:16,257 [HttpRunnerManager:78] [views:log_out] [INFO]- yinquanwang退出
2018-07-02 14:28:18,192 [HttpRunnerManager:45] [views:login] [INFO]- yinquanwang 登录成功
2018-07-02 14:37:16,138 [django.request:118] [exception:handle_uncaught_exception] [ERROR]- Internal Server Error: /api/project_list/1/
Traceback (most recent call last):
  File "E:\Python35\lib\site-packages\django\core\handlers\exception.py", line 35, in inner
    response = get_response(request)
  File "E:\Python35\lib\site-packages\django\core\handlers\base.py", line 128, in _get_response
    response = self.process_exception_by_middleware(e, request)
  File "E:\Python35\lib\site-packages\django\core\handlers\base.py", line 126, in _get_response
    response = wrapped_callback(request, *callback_args, **callback_kwargs)
  File "D:\HttpRunnerManager\HttpRunnerManager\activator.py", line 15, in process
    result = fun(request, index) if index else fun(request)
  File "D:\HttpRunnerManager\ApiManager\views.py", line 311, in project_list
    filter_query = set_filter_session(request)
  File "D:\HttpRunnerManager\ApiManager\utils\common.py", line 442, in set_filter_session
    'belong_project': request.session['project'],
  File "E:\Python35\lib\site-packages\django\contrib\sessions\backends\base.py", line 55, in __getitem__
    return self._session[key]
KeyError: 'project'
2018-07-02 14:37:20,563 [django.request:118] [exception:handle_uncaught_exception] [ERROR]- Internal Server Error: /api/project_list/1/
Traceback (most recent call last):
  File "E:\Python35\lib\site-packages\django\core\handlers\exception.py", line 35, in inner
    response = get_response(request)
  File "E:\Python35\lib\site-packages\django\core\handlers\base.py", line 128, in _get_response
    response = self.process_exception_by_middleware(e, request)
  File "E:\Python35\lib\site-packages\django\core\handlers\base.py", line 126, in _get_response
    response = wrapped_callback(request, *callback_args, **callback_kwargs)
  File "D:\HttpRunnerManager\HttpRunnerManager\activator.py", line 15, in process
    result = fun(request, index) if index else fun(request)
  File "D:\HttpRunnerManager\ApiManager\views.py", line 311, in project_list
    filter_query = set_filter_session(request)
  File "D:\HttpRunnerManager\ApiManager\utils\common.py", line 442, in set_filter_session
    'belong_project': request.session['project'],
  File "E:\Python35\lib\site-packages\django\contrib\sessions\backends\base.py", line 55, in __getitem__
    return self._session[key]
KeyError: 'project'
2018-07-02 14:37:24,899 [HttpRunnerManager:78] [views:log_out] [INFO]- yinquanwang退出
2018-07-02 14:37:26,773 [HttpRunnerManager:45] [views:login] [INFO]- yinquanwang 登录成功
2018-07-02 14:37:30,837 [django.request:118] [exception:handle_uncaught_exception] [ERROR]- Internal Server Error: /api/add_case/
Traceback (most recent call last):
  File "E:\Python35\lib\site-packages\django\core\handlers\exception.py", line 35, in inner
    response = get_response(request)
  File "E:\Python35\lib\site-packages\django\core\handlers\base.py", line 128, in _get_response
    response = self.process_exception_by_middleware(e, request)
  File "E:\Python35\lib\site-packages\django\core\handlers\base.py", line 126, in _get_response
    response = wrapped_callback(request, *callback_args, **callback_kwargs)
  File "D:\HttpRunnerManager\HttpRunnerManager\activator.py", line 15, in process
    result = fun(request, index) if index else fun(request)
  File "D:\HttpRunnerManager\ApiManager\views.py", line 170, in add_case
    msg = case_info_logic(**testcase_info)
  File "D:\HttpRunnerManager\ApiManager\utils\common.py", line 210, in case_info_logic
    test = kwargs.pop('test')
KeyError: 'test'
2018-07-02 14:37:33,775 [django.request:118] [exception:handle_uncaught_exception] [ERROR]- Internal Server Error: /api/add_case/
Traceback (most recent call last):
  File "E:\Python35\lib\site-packages\django\core\handlers\exception.py", line 35, in inner
    response = get_response(request)
  File "E:\Python35\lib\site-packages\django\core\handlers\base.py", line 128, in _get_response
    response = self.process_exception_by_middleware(e, request)
  File "E:\Python35\lib\site-packages\django\core\handlers\base.py", line 126, in _get_response
    response = wrapped_callback(request, *callback_args, **callback_kwargs)
  File "D:\HttpRunnerManager\HttpRunnerManager\activator.py", line 15, in process
    result = fun(request, index) if index else fun(request)
  File "D:\HttpRunnerManager\ApiManager\views.py", line 170, in add_case
    msg = case_info_logic(**testcase_info)
  File "D:\HttpRunnerManager\ApiManager\utils\common.py", line 210, in case_info_logic
    test = kwargs.pop('test')
KeyError: 'test'
2018-07-02 14:39:25,603 [HttpRunnerManager:78] [views:log_out] [INFO]- yinquanwang退出
2018-07-02 14:39:27,918 [HttpRunnerManager:45] [views:login] [INFO]- yinquanwang 登录成功
2018-07-02 14:43:42,829 [HttpRunnerManager:78] [views:log_out] [INFO]- yinquanwang退出
2018-07-02 14:43:44,932 [HttpRunnerManager:45] [views:login] [INFO]- yinquanwang 登录成功
2018-07-02 14:47:52,728 [HttpRunnerManager:78] [views:log_out] [INFO]- yinquanwang退出
2018-07-02 14:47:54,981 [HttpRunnerManager:45] [views:login] [INFO]- yinquanwang 登录成功
2018-07-02 14:55:50,890 [HttpRunnerManager:78] [views:log_out] [INFO]- yinquanwang退出
2018-07-02 14:55:53,036 [HttpRunnerManager:45] [views:login] [INFO]- yinquanwang 登录成功
2018-07-02 14:57:17,859 [django.request:118] [exception:handle_uncaught_exception] [ERROR]- Internal Server Error: /api/module_list/1/
Traceback (most recent call last):
  File "E:\Python35\lib\site-packages\django\core\handlers\exception.py", line 35, in inner
    response = get_response(request)
  File "E:\Python35\lib\site-packages\django\core\handlers\base.py", line 128, in _get_response
    response = self.process_exception_by_middleware(e, request)
  File "E:\Python35\lib\site-packages\django\core\handlers\base.py", line 126, in _get_response
    response = wrapped_callback(request, *callback_args, **callback_kwargs)
  File "D:\HttpRunnerManager\HttpRunnerManager\activator.py", line 15, in process
    result = fun(request, index) if index else fun(request)
  File "D:\HttpRunnerManager\ApiManager\views.py", line 345, in module_list
    filter_query = set_filter_session(request)
  File "D:\HttpRunnerManager\ApiManager\utils\common.py", line 433, in set_filter_session
    request.session['module'] = ModuleInfo.objects.get(id=request.POST.get('module')).module_name
  File "E:\Python35\lib\site-packages\django\db\models\manager.py", line 82, in manager_method
    return getattr(self.get_queryset(), name)(*args, **kwargs)
  File "E:\Python35\lib\site-packages\django\db\models\query.py", line 394, in get
    clone = self.filter(*args, **kwargs)
  File "E:\Python35\lib\site-packages\django\db\models\query.py", line 836, in filter
    return self._filter_or_exclude(False, *args, **kwargs)
  File "E:\Python35\lib\site-packages\django\db\models\query.py", line 854, in _filter_or_exclude
    clone.query.add_q(Q(*args, **kwargs))
  File "E:\Python35\lib\site-packages\django\db\models\sql\query.py", line 1253, in add_q
    clause, _ = self._add_q(q_object, self.used_aliases)
  File "E:\Python35\lib\site-packages\django\db\models\sql\query.py", line 1277, in _add_q
    split_subq=split_subq,
  File "E:\Python35\lib\site-packages\django\db\models\sql\query.py", line 1215, in build_filter
    condition = self.build_lookup(lookups, col, value)
  File "E:\Python35\lib\site-packages\django\db\models\sql\query.py", line 1085, in build_lookup
    lookup = lookup_class(lhs, rhs)
  File "E:\Python35\lib\site-packages\django\db\models\lookups.py", line 18, in __init__
    self.rhs = self.get_prep_lookup()
  File "E:\Python35\lib\site-packages\django\db\models\lookups.py", line 68, in get_prep_lookup
    return self.lhs.output_field.get_prep_value(self.rhs)
  File "E:\Python35\lib\site-packages\django\db\models\fields\__init__.py", line 947, in get_prep_value
    return int(value)
ValueError: invalid literal for int() with base 10: '用例_quant_login_out(登入登出)'
2018-07-02 14:59:50,449 [HttpRunnerManager:78] [views:log_out] [INFO]- yinquanwang退出
2018-07-02 14:59:52,333 [HttpRunnerManager:45] [views:login] [INFO]- yinquanwang 登录成功
2019-11-18 17:44:48,470 [django.request:93] [base:get_response] [WARNING]- Not Found: /
2019-11-18 17:58:27,588 [django.request:93] [base:get_response] [WARNING]- Not Found: /
2019-11-18 17:59:22,654 [HttpRunnerManager:35] [operation:add_register_data] [INFO]- 新增用户：ApiManager.UserInfo.objects
2019-11-18 17:59:28,427 [HttpRunnerManager:60] [views:login] [INFO]- huqiang 登录失败, 请检查用户名或者密码
2019-11-18 17:59:31,397 [HttpRunnerManager:60] [views:login] [INFO]- huqiang 登录失败, 请检查用户名或者密码
2019-11-18 17:59:35,436 [HttpRunnerManager:60] [views:login] [INFO]- huqiang 登录失败, 请检查用户名或者密码
2019-11-18 17:59:38,147 [HttpRunnerManager:60] [views:login] [INFO]- huqiang 登录失败, 请检查用户名或者密码
2019-11-18 17:59:45,268 [HttpRunnerManager:55] [views:login] [INFO]- test 登录成功
2020-01-09 15:43:47,594 [django.request:93] [base:get_response] [WARNING]- Not Found: /
2020-01-09 15:44:22,767 [django.request:118] [exception:handle_uncaught_exception] [ERROR]- Internal Server Error: /api/register/
Traceback (most recent call last):
  File "C:\Users\huqiang\AppData\Local\Programs\Python\Python36\lib\site-packages\django\core\handlers\exception.py", line 35, in inner
    response = get_response(request)
  File "C:\Users\huqiang\AppData\Local\Programs\Python\Python36\lib\site-packages\django\core\handlers\base.py", line 128, in _get_response
    response = self.process_exception_by_middleware(e, request)
  File "C:\Users\huqiang\AppData\Local\Programs\Python\Python36\lib\site-packages\django\core\handlers\base.py", line 126, in _get_response
    response = wrapped_callback(request, *callback_args, **callback_kwargs)
  File "D:\HttpRunnerManager\HttpRunnerManager\activator.py", line 10, in process
    app = __import__("%s.views" % app)
  File "D:\HttpRunnerManager\ApiManager\views.py", line 17, in <module>
    from ApiManager.tasks import main_hrun
  File "D:\HttpRunnerManager\ApiManager\tasks.py", line 16, in <module>
    from httprunner import HttpRunner, logger
ImportError: cannot import name 'HttpRunner'
2020-01-09 15:44:45,466 [django.request:118] [exception:handle_uncaught_exception] [ERROR]- Internal Server Error: /api/register/
Traceback (most recent call last):
  File "C:\Users\huqiang\AppData\Local\Programs\Python\Python36\lib\site-packages\django\core\handlers\exception.py", line 35, in inner
    response = get_response(request)
  File "C:\Users\huqiang\AppData\Local\Programs\Python\Python36\lib\site-packages\django\core\handlers\base.py", line 128, in _get_response
    response = self.process_exception_by_middleware(e, request)
  File "C:\Users\huqiang\AppData\Local\Programs\Python\Python36\lib\site-packages\django\core\handlers\base.py", line 126, in _get_response
    response = wrapped_callback(request, *callback_args, **callback_kwargs)
  File "D:\HttpRunnerManager\HttpRunnerManager\activator.py", line 10, in process
    app = __import__("%s.views" % app)
  File "D:\HttpRunnerManager\ApiManager\views.py", line 17, in <module>
    from ApiManager.tasks import main_hrun
  File "D:\HttpRunnerManager\ApiManager\tasks.py", line 16, in <module>
    from httprunner import HttpRunner, logger
ImportError: cannot import name 'HttpRunner'
2020-01-09 15:46:01,082 [django.request:118] [exception:handle_uncaught_exception] [ERROR]- Internal Server Error: /api/register/
Traceback (most recent call last):
  File "C:\Users\huqiang\AppData\Local\Programs\Python\Python36\lib\site-packages\django\core\handlers\exception.py", line 35, in inner
    response = get_response(request)
  File "C:\Users\huqiang\AppData\Local\Programs\Python\Python36\lib\site-packages\django\core\handlers\base.py", line 128, in _get_response
    response = self.process_exception_by_middleware(e, request)
  File "C:\Users\huqiang\AppData\Local\Programs\Python\Python36\lib\site-packages\django\core\handlers\base.py", line 126, in _get_response
    response = wrapped_callback(request, *callback_args, **callback_kwargs)
  File "D:\HttpRunnerManager\HttpRunnerManager\activator.py", line 10, in process
    app = __import__("%s.views" % app)
  File "D:\HttpRunnerManager\ApiManager\views.py", line 17, in <module>
    from ApiManager.tasks import main_hrun
  File "D:\HttpRunnerManager\ApiManager\tasks.py", line 16, in <module>
    from httprunner import HttpRunner, logger
ImportError: cannot import name 'HttpRunner'
2020-01-09 15:59:16,702 [django.request:118] [exception:handle_uncaught_exception] [ERROR]- Internal Server Error: /api/register/
Traceback (most recent call last):
  File "C:\Users\huqiang\AppData\Local\Programs\Python\Python36\lib\site-packages\django\core\handlers\exception.py", line 35, in inner
    response = get_response(request)
  File "C:\Users\huqiang\AppData\Local\Programs\Python\Python36\lib\site-packages\django\core\handlers\base.py", line 128, in _get_response
    response = self.process_exception_by_middleware(e, request)
  File "C:\Users\huqiang\AppData\Local\Programs\Python\Python36\lib\site-packages\django\core\handlers\base.py", line 126, in _get_response
    response = wrapped_callback(request, *callback_args, **callback_kwargs)
  File "d:\HttpRunnerManager\HttpRunnerManager\activator.py", line 10, in process
    app = __import__("%s.views" % app)
  File "d:\HttpRunnerManager\ApiManager\views.py", line 17, in <module>
    from ApiManager.tasks import main_hrun
  File "d:\HttpRunnerManager\ApiManager\tasks.py", line 16, in <module>
    from httprunner import HttpRunner, logger
ImportError: cannot import name 'HttpRunner'
2020-01-09 16:01:12,851 [django.request:118] [exception:handle_uncaught_exception] [ERROR]- Internal Server Error: /api/register/
Traceback (most recent call last):
  File "C:\Users\huqiang\AppData\Local\Programs\Python\Python36\lib\site-packages\django\core\handlers\exception.py", line 35, in inner
    response = get_response(request)
  File "C:\Users\huqiang\AppData\Local\Programs\Python\Python36\lib\site-packages\django\core\handlers\base.py", line 128, in _get_response
    response = self.process_exception_by_middleware(e, request)
  File "C:\Users\huqiang\AppData\Local\Programs\Python\Python36\lib\site-packages\django\core\handlers\base.py", line 126, in _get_response
    response = wrapped_callback(request, *callback_args, **callback_kwargs)
  File "d:\HttpRunnerManager\HttpRunnerManager\activator.py", line 10, in process
    app = __import__("%s.views" % app)
  File "d:\HttpRunnerManager\ApiManager\views.py", line 27, in <module>
    from httprunner import HttpRunner
ImportError: cannot import name 'HttpRunner'
2020-01-09 16:01:20,350 [django.request:118] [exception:handle_uncaught_exception] [ERROR]- Internal Server Error: /api/register/
Traceback (most recent call last):
  File "C:\Users\huqiang\AppData\Local\Programs\Python\Python36\lib\site-packages\django\core\handlers\exception.py", line 35, in inner
    response = get_response(request)
  File "C:\Users\huqiang\AppData\Local\Programs\Python\Python36\lib\site-packages\django\core\handlers\base.py", line 128, in _get_response
    response = self.process_exception_by_middleware(e, request)
  File "C:\Users\huqiang\AppData\Local\Programs\Python\Python36\lib\site-packages\django\core\handlers\base.py", line 126, in _get_response
    response = wrapped_callback(request, *callback_args, **callback_kwargs)
  File "d:\HttpRunnerManager\HttpRunnerManager\activator.py", line 10, in process
    app = __import__("%s.views" % app)
  File "d:\HttpRunnerManager\ApiManager\views.py", line 27, in <module>
    from httprunner import HttpRunner
ImportError: cannot import name 'HttpRunner'
2020-01-09 16:03:57,080 [HttpRunnerManager:35] [operation:add_register_data] [INFO]- 新增用户：ApiManager.UserInfo.objects
2020-01-09 16:04:03,068 [HttpRunnerManager:60] [views:login] [INFO]- huqiang 登录失败, 请检查用户名或者密码
2020-01-09 16:04:07,350 [HttpRunnerManager:55] [views:login] [INFO]- huqiang 登录成功
2020-01-09 16:32:29,564 [HttpRunnerManager:62] [operation:add_project_data] [INFO]- 项目添加成功：{'project_name': '测试', 'responsible_name': '测试', 'test_user': '测试', 'dev_user': '测试', 'publish_app': '测试', 'simple_desc': '测试', 'other_desc': '测试'}
2020-01-09 16:49:51,094 [HttpRunnerManager:110] [operation:add_module_data] [INFO]- 模块添加成功：{'module_name': 'test01', 'test_user': '测试', 'simple_desc': 'test01', 'other_desc': 'test01', 'belong_project': <ProjectInfo: ProjectInfo object (1)>}
2020-01-09 16:55:07,158 [HttpRunnerManager:154] [operation:add_case_data] [INFO]- 登录用例添加成功: {'test': {'request': {'url': 'http://172.32.12.243:20520/mcloudbank/user/login/pwdLogin', 'method': 'POST', 'json': {'code': '3t93802d53z9', 'deviceId': '838611AF75EBB3009022A9F086AB6413', 'userAccount': '13911112222', 'password': 'UKUYM/XYeFgw/GCaJnFl/KBVzAukYGblFLIBK46qQRz7frzKWiVCdW79gImRJNIFdAg+suiOQ4DIJ8uGicobvN6GRZHmQbrFlaRZqYVaAtpJJ5MOM10U+B+NBJlRrLZOek5t1Ls0ThjXv+sqHlVCVg==|MTIzNDU2Nzg5MDk4NzY1NA==|QIjyn/WT++DFkLC//J78ZA==', 'clientVersion': '3.0.0.1', 'imei': '862552030168899'}, 'headers': {'content-type': 'application/json', 'imei': '862552030168899', 'systemversion': 'vivo X7_android_5.1.1_172.32.16.171', 'system': '2', 'appversion': '3.0.0.1'}}, 'name': '登录', 'extract': [{}]}}
2020-01-09 16:55:14,742 [django.request:118] [exception:handle_uncaught_exception] [ERROR]- Internal Server Error: /api/run_test/
Traceback (most recent call last):
AttributeError: 'HttpRunner' object has no attribute 'summary'
2020-01-09 17:48:17,121 [HttpRunnerManager:60] [views:login] [INFO]- huqiang 登录失败, 请检查用户名或者密码
2020-01-09 17:48:19,274 [HttpRunnerManager:60] [views:login] [INFO]- huqiang 登录失败, 请检查用户名或者密码
2020-01-09 17:48:24,130 [HttpRunnerManager:55] [views:login] [INFO]- huqiang 登录成功
2020-01-14 19:56:48,907 [django.request:93] [base:get_response] [WARNING]- Not Found: /
2020-01-14 19:59:00,946 [HttpRunnerManager:60] [views:login] [INFO]- huqiang 登录失败, 请检查用户名或者密码
2020-01-14 19:59:09,863 [HttpRunnerManager:60] [views:login] [INFO]- huqiang 登录失败, 请检查用户名或者密码
2020-01-14 19:59:15,163 [HttpRunnerManager:55] [views:login] [INFO]- huqiang 登录成功
2020-01-14 19:59:22,848 [HttpRunnerManager:89] [views:log_out] [INFO]- huqiang退出
2020-01-14 19:59:25,564 [HttpRunnerManager:60] [views:login] [INFO]- huqiang 登录失败, 请检查用户名或者密码
2020-01-14 19:59:29,784 [HttpRunnerManager:60] [views:login] [INFO]- huqiang 登录失败, 请检查用户名或者密码
2020-01-14 19:59:35,584 [HttpRunnerManager:55] [views:login] [INFO]- huqiang 登录成功
2020-01-14 20:53:14,556 [django.request:118] [exception:handle_uncaught_exception] [ERROR]- Internal Server Error: /api/test_api/1/
Traceback (most recent call last):
  File "C:\Users\huqiang\AppData\Local\Programs\Python\Python36\lib\site-packages\django\core\handlers\exception.py", line 35, in inner
    response = get_response(request)
  File "C:\Users\huqiang\AppData\Local\Programs\Python\Python36\lib\site-packages\django\core\handlers\base.py", line 128, in _get_response
    response = self.process_exception_by_middleware(e, request)
  File "C:\Users\huqiang\AppData\Local\Programs\Python\Python36\lib\site-packages\django\core\handlers\base.py", line 126, in _get_response
    response = wrapped_callback(request, *callback_args, **callback_kwargs)
  File "D:/HttpRunnerManager\HttpRunnerManager\activator.py", line 12, in process
    fun = getattr(view, fun)
AttributeError: module 'ApiManager.views' has no attribute 'test_api'
2020-01-14 20:53:57,216 [django.request:118] [exception:handle_uncaught_exception] [ERROR]- Internal Server Error: /api/test_api/1/
Traceback (most recent call last):
  File "C:\Users\huqiang\AppData\Local\Programs\Python\Python36\lib\site-packages\django\core\handlers\exception.py", line 35, in inner
    response = get_response(request)
  File "C:\Users\huqiang\AppData\Local\Programs\Python\Python36\lib\site-packages\django\core\handlers\base.py", line 128, in _get_response
    response = self.process_exception_by_middleware(e, request)
  File "C:\Users\huqiang\AppData\Local\Programs\Python\Python36\lib\site-packages\django\core\handlers\base.py", line 126, in _get_response
    response = wrapped_callback(request, *callback_args, **callback_kwargs)
  File "D:/HttpRunnerManager\HttpRunnerManager\activator.py", line 12, in process
    fun = getattr(view, fun)
AttributeError: module 'ApiManager.views' has no attribute 'test_api'
2020-01-14 21:24:43,555 [HttpRunnerManager:154] [operation:add_case_data] [INFO]- 345用例添加成功: {'test': {'request': {'url': '', 'method': 'POST', 'data': {}}, 'name': '345'}}
2020-01-14 21:25:33,971 [HttpRunnerManager:154] [operation:add_case_data] [INFO]- 34用例添加成功: {'test': {'request': {'url': '', 'method': 'POST'}, 'name': '34'}}
2020-01-14 21:48:41,852 [django.request:118] [exception:handle_uncaught_exception] [ERROR]- Internal Server Error: /api/add_api/
Traceback (most recent call last):
  File "C:\Users\huqiang\AppData\Local\Programs\Python\Python36\lib\site-packages\django\core\handlers\exception.py", line 35, in inner
    response = get_response(request)
  File "C:\Users\huqiang\AppData\Local\Programs\Python\Python36\lib\site-packages\django\core\handlers\base.py", line 128, in _get_response
    response = self.process_exception_by_middleware(e, request)
  File "C:\Users\huqiang\AppData\Local\Programs\Python\Python36\lib\site-packages\django\core\handlers\base.py", line 126, in _get_response
    response = wrapped_callback(request, *callback_args, **callback_kwargs)
  File "D:/HttpRunnerManager\HttpRunnerManager\activator.py", line 15, in process
    result = fun(request, index) if index else fun(request)
  File "D:/HttpRunnerManager\ApiManager\views.py", line 39, in wrapper
    return func(request, *args, **kwargs)
  File "D:/HttpRunnerManager\ApiManager\views.py", line 201, in add_api
    return render_to_response('add_api.html', manage_info)
  File "C:\Users\huqiang\AppData\Local\Programs\Python\Python36\lib\site-packages\django\shortcuts.py", line 27, in render_to_response
    content = loader.render_to_string(template_name, context, using=using)
  File "C:\Users\huqiang\AppData\Local\Programs\Python\Python36\lib\site-packages\django\template\loader.py", line 61, in render_to_string
    template = get_template(template_name, using=using)
  File "C:\Users\huqiang\AppData\Local\Programs\Python\Python36\lib\site-packages\django\template\loader.py", line 19, in get_template
    raise TemplateDoesNotExist(template_name, chain=chain)
django.template.exceptions.TemplateDoesNotExist: add_api.html
2020-01-20 09:59:08,808 [django.request:93] [base:get_response] [WARNING]- Not Found: /
2020-01-20 10:00:03,083 [HttpRunnerManager:60] [views:login] [INFO]- huqiang 登录失败, 请检查用户名或者密码
2020-01-20 10:00:04,703 [HttpRunnerManager:60] [views:login] [INFO]- huqiang 登录失败, 请检查用户名或者密码
2020-01-20 10:00:08,335 [HttpRunnerManager:60] [views:login] [INFO]- huqiang 登录失败, 请检查用户名或者密码
2020-01-20 10:00:12,906 [HttpRunnerManager:60] [views:login] [INFO]- huqiang 登录失败, 请检查用户名或者密码
2020-01-20 10:00:16,024 [HttpRunnerManager:55] [views:login] [INFO]- huqiang 登录成功
2020-01-20 10:10:38,398 [HttpRunnerManager:154] [operation:add_case_data] [INFO]- ll用例添加成功: {'test': {'request': {'url': '2', 'method': 'POST', 'data': {'3': '4'}}, 'name': 'll'}}
2020-01-20 10:21:52,478 [HttpRunnerManager:154] [operation:add_case_data] [INFO]- 5用例添加成功: {'test': {'request': {'url': '2', 'method': 'POST', 'data': {'3': '4'}}, 'name': '5'}}
2020-01-20 10:30:52,615 [HttpRunnerManager:154] [operation:add_case_data] [INFO]- 登录33333用例添加成功: {'test': {'request': {'url': '44', 'method': 'POST', 'data': {'5': '6'}}, 'name': '登录33333'}}
2020-01-20 10:31:23,932 [HttpRunnerManager:154] [operation:add_case_data] [INFO]- 34用例添加成功: {'test': {'request': {'url': '34', 'method': 'POST', 'data': {'34': '3434'}}, 'name': '34'}}
2020-01-20 10:32:14,350 [django.request:118] [exception:handle_uncaught_exception] [ERROR]- Internal Server Error: /api/add_case/
Traceback (most recent call last):
  File "C:\Users\huqiang\AppData\Local\Programs\Python\Python36\lib\site-packages\django\core\handlers\exception.py", line 35, in inner
    response = get_response(request)
  File "C:\Users\huqiang\AppData\Local\Programs\Python\Python36\lib\site-packages\django\core\handlers\base.py", line 128, in _get_response
    response = self.process_exception_by_middleware(e, request)
  File "C:\Users\huqiang\AppData\Local\Programs\Python\Python36\lib\site-packages\django\core\handlers\base.py", line 126, in _get_response
    response = wrapped_callback(request, *callback_args, **callback_kwargs)
  File "D:/HttpRunnerManager\HttpRunnerManager\activator.py", line 15, in process
    result = fun(request, index) if index else fun(request)
  File "D:/HttpRunnerManager\ApiManager\views.py", line 39, in wrapper
    return func(request, *args, **kwargs)
  File "D:/HttpRunnerManager\ApiManager\views.py", line 175, in add_case
    msg = case_info_logic(**testcase_info)
  File "D:/HttpRunnerManager\ApiManager\utils\common.py", line 314, in case_info_logic
    return add_case_data(type, **kwargs)
  File "D:/HttpRunnerManager\ApiManager\utils\operation.py", line 144, in add_case_data
    belong_module = ModuleInfo.objects.get_module_name(module, type=False)
  File "D:/HttpRunnerManager\ApiManager\managers.py", line 87, in get_module_name
    return self.get(id=module_name)
  File "C:\Users\huqiang\AppData\Local\Programs\Python\Python36\lib\site-packages\django\db\models\manager.py", line 82, in manager_method
    return getattr(self.get_queryset(), name)(*args, **kwargs)
  File "C:\Users\huqiang\AppData\Local\Programs\Python\Python36\lib\site-packages\django\db\models\query.py", line 403, in get
    self.model._meta.object_name
ApiManager.models.DoesNotExist: ModuleInfo matching query does not exist.
2020-01-20 10:32:58,622 [HttpRunnerManager:154] [operation:add_case_data] [INFO]- 34534534533用例添加成功: {'test': {'request': {'url': '345345', 'method': 'POST', 'data': {'345345': '345345'}}, 'name': '34534534533'}}
2020-01-20 10:34:27,563 [HttpRunnerManager:154] [operation:add_case_data] [INFO]- 34234234用例添加成功: {'test': {'request': {'url': '23423', 'method': 'POST', 'data': {'222': '222222222222'}}, 'name': '34234234'}}
2020-01-20 10:39:08,678 [HttpRunnerManager:154] [operation:add_case_data] [INFO]- 34324234用例添加成功: {'test': {'request': {'url': '222222222222222', 'method': 'POST', 'data': {'3333333333': '333333333333333333333333'}}, 'name': '34324234'}}
2020-01-20 11:25:00,805 [django.request:118] [exception:handle_uncaught_exception] [ERROR]- Internal Server Error: /api/add_api/
Traceback (most recent call last):
  File "C:\Users\huqiang\AppData\Local\Programs\Python\Python36\lib\site-packages\django\core\handlers\exception.py", line 35, in inner
    response = get_response(request)
  File "C:\Users\huqiang\AppData\Local\Programs\Python\Python36\lib\site-packages\django\core\handlers\base.py", line 128, in _get_response
    response = self.process_exception_by_middleware(e, request)
  File "C:\Users\huqiang\AppData\Local\Programs\Python\Python36\lib\site-packages\django\core\handlers\base.py", line 126, in _get_response
    response = wrapped_callback(request, *callback_args, **callback_kwargs)
  File "D:/HttpRunnerManager\HttpRunnerManager\activator.py", line 15, in process
    result = fun(request, index) if index else fun(request)
  File "D:/HttpRunnerManager\ApiManager\views.py", line 39, in wrapper
    return func(request, *args, **kwargs)
  File "D:/HttpRunnerManager\ApiManager\views.py", line 194, in add_api
    msg = api_info_logic(**testcase_info)
  File "D:/HttpRunnerManager\ApiManager\utils\common.py", line 408, in api_info_logic
    return add_api_data(type, **kwargs)
  File "D:/HttpRunnerManager\ApiManager\utils\operation.py", line 181, in add_api_data
    module = ApiInfo.get('module')
AttributeError: type object 'ApiInfo' has no attribute 'get'
2020-01-20 14:16:25,859 [django.request:118] [exception:handle_uncaught_exception] [ERROR]- Internal Server Error: /api/add_api/
Traceback (most recent call last):
  File "C:\Users\huqiang\AppData\Local\Programs\Python\Python36\lib\site-packages\django\core\handlers\exception.py", line 35, in inner
    response = get_response(request)
  File "C:\Users\huqiang\AppData\Local\Programs\Python\Python36\lib\site-packages\django\core\handlers\base.py", line 128, in _get_response
    response = self.process_exception_by_middleware(e, request)
  File "C:\Users\huqiang\AppData\Local\Programs\Python\Python36\lib\site-packages\django\core\handlers\base.py", line 126, in _get_response
    response = wrapped_callback(request, *callback_args, **callback_kwargs)
  File "D:/HttpRunnerManager\HttpRunnerManager\activator.py", line 15, in process
    result = fun(request, index) if index else fun(request)
  File "D:/HttpRunnerManager\ApiManager\views.py", line 39, in wrapper
    return func(request, *args, **kwargs)
  File "D:/HttpRunnerManager\ApiManager\views.py", line 194, in add_api
    msg = api_info_logic(**testcase_info)
  File "D:/HttpRunnerManager\ApiManager\utils\common.py", line 408, in api_info_logic
    return add_api_data(type, **kwargs)
  File "D:/HttpRunnerManager\ApiManager\utils\operation.py", line 181, in add_api_data
    module = ApiInfo.get('module')
AttributeError: type object 'ApiInfo' has no attribute 'get'
2020-01-20 14:18:28,927 [django.request:118] [exception:handle_uncaught_exception] [ERROR]- Internal Server Error: /api/add_api/
Traceback (most recent call last):
  File "C:\Users\huqiang\AppData\Local\Programs\Python\Python36\lib\site-packages\django\core\handlers\exception.py", line 35, in inner
    response = get_response(request)
  File "C:\Users\huqiang\AppData\Local\Programs\Python\Python36\lib\site-packages\django\core\handlers\base.py", line 128, in _get_response
    response = self.process_exception_by_middleware(e, request)
  File "C:\Users\huqiang\AppData\Local\Programs\Python\Python36\lib\site-packages\django\core\handlers\base.py", line 126, in _get_response
    response = wrapped_callback(request, *callback_args, **callback_kwargs)
  File "D:/HttpRunnerManager\HttpRunnerManager\activator.py", line 15, in process
    result = fun(request, index) if index else fun(request)
  File "D:/HttpRunnerManager\ApiManager\views.py", line 39, in wrapper
    return func(request, *args, **kwargs)
  File "D:/HttpRunnerManager\ApiManager\views.py", line 194, in add_api
    msg = api_info_logic(**testcase_info)
  File "D:/HttpRunnerManager\ApiManager\utils\common.py", line 408, in api_info_logic
    return add_api_data(type, **kwargs)
  File "D:/HttpRunnerManager\ApiManager\utils\operation.py", line 181, in add_api_data
    module = ApiInfo.get('module')
AttributeError: type object 'ApiInfo' has no attribute 'get'
2020-01-20 14:18:42,536 [django.request:118] [exception:handle_uncaught_exception] [ERROR]- Internal Server Error: /api/add_api/
Traceback (most recent call last):
  File "C:\Users\huqiang\AppData\Local\Programs\Python\Python36\lib\site-packages\django\core\handlers\exception.py", line 35, in inner
    response = get_response(request)
  File "C:\Users\huqiang\AppData\Local\Programs\Python\Python36\lib\site-packages\django\core\handlers\base.py", line 128, in _get_response
    response = self.process_exception_by_middleware(e, request)
  File "C:\Users\huqiang\AppData\Local\Programs\Python\Python36\lib\site-packages\django\core\handlers\base.py", line 126, in _get_response
    response = wrapped_callback(request, *callback_args, **callback_kwargs)
  File "D:/HttpRunnerManager\HttpRunnerManager\activator.py", line 15, in process
    result = fun(request, index) if index else fun(request)
  File "D:/HttpRunnerManager\ApiManager\views.py", line 39, in wrapper
    return func(request, *args, **kwargs)
  File "D:/HttpRunnerManager\ApiManager\views.py", line 194, in add_api
    msg = api_info_logic(**testcase_info)
  File "D:/HttpRunnerManager\ApiManager\utils\common.py", line 408, in api_info_logic
    return add_api_data(type, **kwargs)
  File "D:/HttpRunnerManager\ApiManager\utils\operation.py", line 181, in add_api_data
    module = ApiInfo.get('module')
AttributeError: type object 'ApiInfo' has no attribute 'get'
2020-01-20 15:04:54,367 [django.request:118] [exception:handle_uncaught_exception] [ERROR]- Internal Server Error: /api/test_api/1/
Traceback (most recent call last):
  File "C:\Users\huqiang\AppData\Local\Programs\Python\Python36\lib\site-packages\django\core\handlers\exception.py", line 35, in inner
    response = get_response(request)
  File "C:\Users\huqiang\AppData\Local\Programs\Python\Python36\lib\site-packages\django\core\handlers\base.py", line 128, in _get_response
    response = self.process_exception_by_middleware(e, request)
  File "C:\Users\huqiang\AppData\Local\Programs\Python\Python36\lib\site-packages\django\core\handlers\base.py", line 126, in _get_response
    response = wrapped_callback(request, *callback_args, **callback_kwargs)
  File "D:/HttpRunnerManager\HttpRunnerManager\activator.py", line 15, in process
    result = fun(request, index) if index else fun(request)
  File "D:/HttpRunnerManager\ApiManager\views.py", line 39, in wrapper
    return func(request, *args, **kwargs)
  File "D:/HttpRunnerManager\ApiManager\views.py", line 424, in test_api
    ApiInfo, filter_query, '/api/test_list/', id)
  File "D:/HttpRunnerManager\ApiManager\utils\pagination.py", line 137, in get_pager_info
    obj = obj.filter(type__exact=1) if url == '/api/test_list/' else obj.filter(type__exact=2)
  File "C:\Users\huqiang\AppData\Local\Programs\Python\Python36\lib\site-packages\django\db\models\manager.py", line 82, in manager_method
    return getattr(self.get_queryset(), name)(*args, **kwargs)
  File "C:\Users\huqiang\AppData\Local\Programs\Python\Python36\lib\site-packages\django\db\models\query.py", line 836, in filter
    return self._filter_or_exclude(False, *args, **kwargs)
  File "C:\Users\huqiang\AppData\Local\Programs\Python\Python36\lib\site-packages\django\db\models\query.py", line 854, in _filter_or_exclude
    clone.query.add_q(Q(*args, **kwargs))
  File "C:\Users\huqiang\AppData\Local\Programs\Python\Python36\lib\site-packages\django\db\models\sql\query.py", line 1253, in add_q
    clause, _ = self._add_q(q_object, self.used_aliases)
  File "C:\Users\huqiang\AppData\Local\Programs\Python\Python36\lib\site-packages\django\db\models\sql\query.py", line 1277, in _add_q
    split_subq=split_subq,
  File "C:\Users\huqiang\AppData\Local\Programs\Python\Python36\lib\site-packages\django\db\models\sql\query.py", line 1153, in build_filter
    lookups, parts, reffed_expression = self.solve_lookup_type(arg)
  File "C:\Users\huqiang\AppData\Local\Programs\Python\Python36\lib\site-packages\django\db\models\sql\query.py", line 1015, in solve_lookup_type
    _, field, _, lookup_parts = self.names_to_path(lookup_splitted, self.get_meta())
  File "C:\Users\huqiang\AppData\Local\Programs\Python\Python36\lib\site-packages\django\db\models\sql\query.py", line 1379, in names_to_path
    "Choices are: %s" % (name, ", ".join(available)))
django.core.exceptions.FieldError: Cannot resolve keyword 'type' into field. Choices are: Api_author, Api_include, Api_name, Api_request, Api_type, belong_module, belong_module_id, belong_project, create_time, id, update_time
2020-01-20 15:05:04,640 [django.request:118] [exception:handle_uncaught_exception] [ERROR]- Internal Server Error: /api/test_api/1/
Traceback (most recent call last):
  File "C:\Users\huqiang\AppData\Local\Programs\Python\Python36\lib\site-packages\django\core\handlers\exception.py", line 35, in inner
    response = get_response(request)
  File "C:\Users\huqiang\AppData\Local\Programs\Python\Python36\lib\site-packages\django\core\handlers\base.py", line 128, in _get_response
    response = self.process_exception_by_middleware(e, request)
  File "C:\Users\huqiang\AppData\Local\Programs\Python\Python36\lib\site-packages\django\core\handlers\base.py", line 126, in _get_response
    response = wrapped_callback(request, *callback_args, **callback_kwargs)
  File "D:/HttpRunnerManager\HttpRunnerManager\activator.py", line 15, in process
    result = fun(request, index) if index else fun(request)
  File "D:/HttpRunnerManager\ApiManager\views.py", line 39, in wrapper
    return func(request, *args, **kwargs)
  File "D:/HttpRunnerManager\ApiManager\views.py", line 424, in test_api
    ApiInfo, filter_query, '/api/test_list/', id)
  File "D:/HttpRunnerManager\ApiManager\utils\pagination.py", line 137, in get_pager_info
    obj = obj.filter(type__exact=1) if url == '/api/test_list/' else obj.filter(type__exact=2)
  File "C:\Users\huqiang\AppData\Local\Programs\Python\Python36\lib\site-packages\django\db\models\manager.py", line 82, in manager_method
    return getattr(self.get_queryset(), name)(*args, **kwargs)
  File "C:\Users\huqiang\AppData\Local\Programs\Python\Python36\lib\site-packages\django\db\models\query.py", line 836, in filter
    return self._filter_or_exclude(False, *args, **kwargs)
  File "C:\Users\huqiang\AppData\Local\Programs\Python\Python36\lib\site-packages\django\db\models\query.py", line 854, in _filter_or_exclude
    clone.query.add_q(Q(*args, **kwargs))
  File "C:\Users\huqiang\AppData\Local\Programs\Python\Python36\lib\site-packages\django\db\models\sql\query.py", line 1253, in add_q
    clause, _ = self._add_q(q_object, self.used_aliases)
  File "C:\Users\huqiang\AppData\Local\Programs\Python\Python36\lib\site-packages\django\db\models\sql\query.py", line 1277, in _add_q
    split_subq=split_subq,
  File "C:\Users\huqiang\AppData\Local\Programs\Python\Python36\lib\site-packages\django\db\models\sql\query.py", line 1153, in build_filter
    lookups, parts, reffed_expression = self.solve_lookup_type(arg)
  File "C:\Users\huqiang\AppData\Local\Programs\Python\Python36\lib\site-packages\django\db\models\sql\query.py", line 1015, in solve_lookup_type
    _, field, _, lookup_parts = self.names_to_path(lookup_splitted, self.get_meta())
  File "C:\Users\huqiang\AppData\Local\Programs\Python\Python36\lib\site-packages\django\db\models\sql\query.py", line 1379, in names_to_path
    "Choices are: %s" % (name, ", ".join(available)))
django.core.exceptions.FieldError: Cannot resolve keyword 'type' into field. Choices are: Api_author, Api_include, Api_name, Api_request, Api_type, belong_module, belong_module_id, belong_project, create_time, id, update_time
2020-01-20 15:17:56,584 [django.request:118] [exception:handle_uncaught_exception] [ERROR]- Internal Server Error: /api/test_api/1/
Traceback (most recent call last):
  File "C:\Users\huqiang\AppData\Local\Programs\Python\Python36\lib\site-packages\django\core\handlers\exception.py", line 35, in inner
    response = get_response(request)
  File "C:\Users\huqiang\AppData\Local\Programs\Python\Python36\lib\site-packages\django\core\handlers\base.py", line 128, in _get_response
    response = self.process_exception_by_middleware(e, request)
  File "C:\Users\huqiang\AppData\Local\Programs\Python\Python36\lib\site-packages\django\core\handlers\base.py", line 126, in _get_response
    response = wrapped_callback(request, *callback_args, **callback_kwargs)
  File "D:/HttpRunnerManager\HttpRunnerManager\activator.py", line 15, in process
    result = fun(request, index) if index else fun(request)
  File "D:/HttpRunnerManager\ApiManager\views.py", line 39, in wrapper
    return func(request, *args, **kwargs)
  File "D:/HttpRunnerManager\ApiManager\views.py", line 424, in test_api
    ApiInfo, filter_query, '/api/test_list/', id)
  File "D:/HttpRunnerManager\ApiManager\utils\pagination.py", line 137, in get_pager_info
    obj = obj.filter(type__exact=1) if url == '/api/test_list/' else obj.filter(type__exact=2)
  File "C:\Users\huqiang\AppData\Local\Programs\Python\Python36\lib\site-packages\django\db\models\manager.py", line 82, in manager_method
    return getattr(self.get_queryset(), name)(*args, **kwargs)
  File "C:\Users\huqiang\AppData\Local\Programs\Python\Python36\lib\site-packages\django\db\models\query.py", line 836, in filter
    return self._filter_or_exclude(False, *args, **kwargs)
  File "C:\Users\huqiang\AppData\Local\Programs\Python\Python36\lib\site-packages\django\db\models\query.py", line 854, in _filter_or_exclude
    clone.query.add_q(Q(*args, **kwargs))
  File "C:\Users\huqiang\AppData\Local\Programs\Python\Python36\lib\site-packages\django\db\models\sql\query.py", line 1253, in add_q
    clause, _ = self._add_q(q_object, self.used_aliases)
  File "C:\Users\huqiang\AppData\Local\Programs\Python\Python36\lib\site-packages\django\db\models\sql\query.py", line 1277, in _add_q
    split_subq=split_subq,
  File "C:\Users\huqiang\AppData\Local\Programs\Python\Python36\lib\site-packages\django\db\models\sql\query.py", line 1153, in build_filter
    lookups, parts, reffed_expression = self.solve_lookup_type(arg)
  File "C:\Users\huqiang\AppData\Local\Programs\Python\Python36\lib\site-packages\django\db\models\sql\query.py", line 1015, in solve_lookup_type
    _, field, _, lookup_parts = self.names_to_path(lookup_splitted, self.get_meta())
  File "C:\Users\huqiang\AppData\Local\Programs\Python\Python36\lib\site-packages\django\db\models\sql\query.py", line 1379, in names_to_path
    "Choices are: %s" % (name, ", ".join(available)))
django.core.exceptions.FieldError: Cannot resolve keyword 'type' into field. Choices are: Api_author, Api_include, Api_name, Api_request, Api_type, belong_module, belong_module_id, belong_project, create_time, id, update_time
2020-01-20 15:20:03,956 [django.request:118] [exception:handle_uncaught_exception] [ERROR]- Internal Server Error: /api/test_api/1/
Traceback (most recent call last):
  File "C:\Users\huqiang\AppData\Local\Programs\Python\Python36\lib\site-packages\django\core\handlers\exception.py", line 35, in inner
    response = get_response(request)
  File "C:\Users\huqiang\AppData\Local\Programs\Python\Python36\lib\site-packages\django\core\handlers\base.py", line 128, in _get_response
    response = self.process_exception_by_middleware(e, request)
  File "C:\Users\huqiang\AppData\Local\Programs\Python\Python36\lib\site-packages\django\core\handlers\base.py", line 126, in _get_response
    response = wrapped_callback(request, *callback_args, **callback_kwargs)
  File "D:/HttpRunnerManager\HttpRunnerManager\activator.py", line 15, in process
    result = fun(request, index) if index else fun(request)
  File "D:/HttpRunnerManager\ApiManager\views.py", line 39, in wrapper
    return func(request, *args, **kwargs)
  File "D:/HttpRunnerManager\ApiManager\views.py", line 424, in test_api
    ApiInfo, filter_query, '/api/test_list/', id)
  File "D:/HttpRunnerManager\ApiManager\utils\pagination.py", line 137, in get_pager_info
    obj = obj.filter(type__exact=1) if url == '/api/test_list/' else obj.filter(type__exact=2)
  File "C:\Users\huqiang\AppData\Local\Programs\Python\Python36\lib\site-packages\django\db\models\manager.py", line 82, in manager_method
    return getattr(self.get_queryset(), name)(*args, **kwargs)
  File "C:\Users\huqiang\AppData\Local\Programs\Python\Python36\lib\site-packages\django\db\models\query.py", line 836, in filter
    return self._filter_or_exclude(False, *args, **kwargs)
  File "C:\Users\huqiang\AppData\Local\Programs\Python\Python36\lib\site-packages\django\db\models\query.py", line 854, in _filter_or_exclude
    clone.query.add_q(Q(*args, **kwargs))
  File "C:\Users\huqiang\AppData\Local\Programs\Python\Python36\lib\site-packages\django\db\models\sql\query.py", line 1253, in add_q
    clause, _ = self._add_q(q_object, self.used_aliases)
  File "C:\Users\huqiang\AppData\Local\Programs\Python\Python36\lib\site-packages\django\db\models\sql\query.py", line 1277, in _add_q
    split_subq=split_subq,
  File "C:\Users\huqiang\AppData\Local\Programs\Python\Python36\lib\site-packages\django\db\models\sql\query.py", line 1153, in build_filter
    lookups, parts, reffed_expression = self.solve_lookup_type(arg)
  File "C:\Users\huqiang\AppData\Local\Programs\Python\Python36\lib\site-packages\django\db\models\sql\query.py", line 1015, in solve_lookup_type
    _, field, _, lookup_parts = self.names_to_path(lookup_splitted, self.get_meta())
  File "C:\Users\huqiang\AppData\Local\Programs\Python\Python36\lib\site-packages\django\db\models\sql\query.py", line 1379, in names_to_path
    "Choices are: %s" % (name, ", ".join(available)))
django.core.exceptions.FieldError: Cannot resolve keyword 'type' into field. Choices are: Api_author, Api_include, Api_name, Api_request, Api_type, belong_module, belong_module_id, belong_project, create_time, id, update_time
2020-01-20 15:20:52,607 [django.request:118] [exception:handle_uncaught_exception] [ERROR]- Internal Server Error: /api/add_api/
Traceback (most recent call last):
  File "C:\Users\huqiang\AppData\Local\Programs\Python\Python36\lib\site-packages\django\core\handlers\exception.py", line 35, in inner
    response = get_response(request)
  File "C:\Users\huqiang\AppData\Local\Programs\Python\Python36\lib\site-packages\django\core\handlers\base.py", line 128, in _get_response
    response = self.process_exception_by_middleware(e, request)
  File "C:\Users\huqiang\AppData\Local\Programs\Python\Python36\lib\site-packages\django\core\handlers\base.py", line 126, in _get_response
    response = wrapped_callback(request, *callback_args, **callback_kwargs)
  File "D:/HttpRunnerManager\HttpRunnerManager\activator.py", line 15, in process
    result = fun(request, index) if index else fun(request)
  File "D:/HttpRunnerManager\ApiManager\views.py", line 39, in wrapper
    return func(request, *args, **kwargs)
  File "D:/HttpRunnerManager\ApiManager\views.py", line 194, in add_api
    msg = api_info_logic(**testcase_info)
  File "D:/HttpRunnerManager\ApiManager\utils\common.py", line 408, in api_info_logic
    return add_api_data(type, **kwargs)
  File "D:/HttpRunnerManager\ApiManager\utils\operation.py", line 191, in add_api_data
    if api_opt.get_api_name(name, module, project) < 1:
AttributeError: 'TestCaseInfoManager' object has no attribute 'get_api_name'
2020-01-20 15:23:25,364 [django.request:118] [exception:handle_uncaught_exception] [ERROR]- Internal Server Error: /api/add_api/
Traceback (most recent call last):
  File "C:\Users\huqiang\AppData\Local\Programs\Python\Python36\lib\site-packages\django\core\handlers\exception.py", line 35, in inner
    response = get_response(request)
  File "C:\Users\huqiang\AppData\Local\Programs\Python\Python36\lib\site-packages\django\core\handlers\base.py", line 128, in _get_response
    response = self.process_exception_by_middleware(e, request)
  File "C:\Users\huqiang\AppData\Local\Programs\Python\Python36\lib\site-packages\django\core\handlers\base.py", line 126, in _get_response
    response = wrapped_callback(request, *callback_args, **callback_kwargs)
  File "D:/HttpRunnerManager\HttpRunnerManager\activator.py", line 15, in process
    result = fun(request, index) if index else fun(request)
  File "D:/HttpRunnerManager\ApiManager\views.py", line 39, in wrapper
    return func(request, *args, **kwargs)
  File "D:/HttpRunnerManager\ApiManager\views.py", line 194, in add_api
    msg = api_info_logic(**testcase_info)
  File "D:/HttpRunnerManager\ApiManager\utils\common.py", line 408, in api_info_logic
    return add_api_data(type, **kwargs)
  File "D:/HttpRunnerManager\ApiManager\utils\operation.py", line 191, in add_api_data
    if api_opt.get_api_name(name, module, project) < 1:
AttributeError: 'TestCaseInfoManager' object has no attribute 'get_api_name'
2020-01-20 15:23:57,735 [django.request:118] [exception:handle_uncaught_exception] [ERROR]- Internal Server Error: /api/add_api/
Traceback (most recent call last):
  File "C:\Users\huqiang\AppData\Local\Programs\Python\Python36\lib\site-packages\django\core\handlers\exception.py", line 35, in inner
    response = get_response(request)
  File "C:\Users\huqiang\AppData\Local\Programs\Python\Python36\lib\site-packages\django\core\handlers\base.py", line 128, in _get_response
    response = self.process_exception_by_middleware(e, request)
  File "C:\Users\huqiang\AppData\Local\Programs\Python\Python36\lib\site-packages\django\core\handlers\base.py", line 126, in _get_response
    response = wrapped_callback(request, *callback_args, **callback_kwargs)
  File "D:/HttpRunnerManager\HttpRunnerManager\activator.py", line 15, in process
    result = fun(request, index) if index else fun(request)
  File "D:/HttpRunnerManager\ApiManager\views.py", line 39, in wrapper
    return func(request, *args, **kwargs)
  File "D:/HttpRunnerManager\ApiManager\views.py", line 194, in add_api
    msg = api_info_logic(**testcase_info)
  File "D:/HttpRunnerManager\ApiManager\utils\common.py", line 408, in api_info_logic
    return add_api_data(type, **kwargs)
  File "D:/HttpRunnerManager\ApiManager\utils\operation.py", line 191, in add_api_data
    if api_opt.get_api_name(name, module, project) < 1:
AttributeError: 'TestCaseInfoManager' object has no attribute 'get_api_name'
2020-01-20 15:27:37,755 [django.request:118] [exception:handle_uncaught_exception] [ERROR]- Internal Server Error: /api/add_api/
Traceback (most recent call last):
  File "C:\Users\huqiang\AppData\Local\Programs\Python\Python36\lib\site-packages\django\core\handlers\exception.py", line 35, in inner
    response = get_response(request)
  File "C:\Users\huqiang\AppData\Local\Programs\Python\Python36\lib\site-packages\django\core\handlers\base.py", line 128, in _get_response
    response = self.process_exception_by_middleware(e, request)
  File "C:\Users\huqiang\AppData\Local\Programs\Python\Python36\lib\site-packages\django\core\handlers\base.py", line 126, in _get_response
    response = wrapped_callback(request, *callback_args, **callback_kwargs)
  File "D:/HttpRunnerManager\HttpRunnerManager\activator.py", line 15, in process
    result = fun(request, index) if index else fun(request)
  File "D:/HttpRunnerManager\ApiManager\views.py", line 39, in wrapper
    return func(request, *args, **kwargs)
  File "D:/HttpRunnerManager\ApiManager\views.py", line 194, in add_api
    msg = api_info_logic(**testcase_info)
  File "D:/HttpRunnerManager\ApiManager\utils\common.py", line 408, in api_info_logic
    return add_api_data(type, **kwargs)
  File "D:/HttpRunnerManager\ApiManager\utils\operation.py", line 191, in add_api_data
    if api_opt.get_api_name(name, module, project) < 1:
  File "D:/HttpRunnerManager\ApiManager\managers.py", line 176, in get_api_name
    return self.filter(belong_module__id=module_name).filter(name__exact=name).filter(
  File "C:\Users\huqiang\AppData\Local\Programs\Python\Python36\lib\site-packages\django\db\models\query.py", line 836, in filter
    return self._filter_or_exclude(False, *args, **kwargs)
  File "C:\Users\huqiang\AppData\Local\Programs\Python\Python36\lib\site-packages\django\db\models\query.py", line 854, in _filter_or_exclude
    clone.query.add_q(Q(*args, **kwargs))
  File "C:\Users\huqiang\AppData\Local\Programs\Python\Python36\lib\site-packages\django\db\models\sql\query.py", line 1253, in add_q
    clause, _ = self._add_q(q_object, self.used_aliases)
  File "C:\Users\huqiang\AppData\Local\Programs\Python\Python36\lib\site-packages\django\db\models\sql\query.py", line 1277, in _add_q
    split_subq=split_subq,
  File "C:\Users\huqiang\AppData\Local\Programs\Python\Python36\lib\site-packages\django\db\models\sql\query.py", line 1153, in build_filter
    lookups, parts, reffed_expression = self.solve_lookup_type(arg)
  File "C:\Users\huqiang\AppData\Local\Programs\Python\Python36\lib\site-packages\django\db\models\sql\query.py", line 1015, in solve_lookup_type
    _, field, _, lookup_parts = self.names_to_path(lookup_splitted, self.get_meta())
  File "C:\Users\huqiang\AppData\Local\Programs\Python\Python36\lib\site-packages\django\db\models\sql\query.py", line 1379, in names_to_path
    "Choices are: %s" % (name, ", ".join(available)))
django.core.exceptions.FieldError: Cannot resolve keyword 'name' into field. Choices are: Api_author, Api_include, Api_name, Api_request, Api_type, belong_module, belong_module_id, belong_project, create_time, id, update_time
2020-01-20 15:27:37,760 [django.request:118] [exception:handle_uncaught_exception] [ERROR]- Internal Server Error: /api/add_api/
Traceback (most recent call last):
  File "C:\Users\huqiang\AppData\Local\Programs\Python\Python36\lib\site-packages\django\core\handlers\exception.py", line 35, in inner
    response = get_response(request)
  File "C:\Users\huqiang\AppData\Local\Programs\Python\Python36\lib\site-packages\django\core\handlers\base.py", line 128, in _get_response
    response = self.process_exception_by_middleware(e, request)
  File "C:\Users\huqiang\AppData\Local\Programs\Python\Python36\lib\site-packages\django\core\handlers\base.py", line 126, in _get_response
    response = wrapped_callback(request, *callback_args, **callback_kwargs)
  File "D:/HttpRunnerManager\HttpRunnerManager\activator.py", line 15, in process
    result = fun(request, index) if index else fun(request)
  File "D:/HttpRunnerManager\ApiManager\views.py", line 39, in wrapper
    return func(request, *args, **kwargs)
  File "D:/HttpRunnerManager\ApiManager\views.py", line 194, in add_api
    msg = api_info_logic(**testcase_info)
  File "D:/HttpRunnerManager\ApiManager\utils\common.py", line 408, in api_info_logic
    return add_api_data(type, **kwargs)
  File "D:/HttpRunnerManager\ApiManager\utils\operation.py", line 191, in add_api_data
    if api_opt.get_api_name(name, module, project) < 1:
  File "D:/HttpRunnerManager\ApiManager\managers.py", line 176, in get_api_name
    return self.filter(belong_module__id=module_name).filter(name__exact=name).filter(
  File "C:\Users\huqiang\AppData\Local\Programs\Python\Python36\lib\site-packages\django\db\models\query.py", line 836, in filter
    return self._filter_or_exclude(False, *args, **kwargs)
  File "C:\Users\huqiang\AppData\Local\Programs\Python\Python36\lib\site-packages\django\db\models\query.py", line 854, in _filter_or_exclude
    clone.query.add_q(Q(*args, **kwargs))
  File "C:\Users\huqiang\AppData\Local\Programs\Python\Python36\lib\site-packages\django\db\models\sql\query.py", line 1253, in add_q
    clause, _ = self._add_q(q_object, self.used_aliases)
  File "C:\Users\huqiang\AppData\Local\Programs\Python\Python36\lib\site-packages\django\db\models\sql\query.py", line 1277, in _add_q
    split_subq=split_subq,
  File "C:\Users\huqiang\AppData\Local\Programs\Python\Python36\lib\site-packages\django\db\models\sql\query.py", line 1153, in build_filter
    lookups, parts, reffed_expression = self.solve_lookup_type(arg)
  File "C:\Users\huqiang\AppData\Local\Programs\Python\Python36\lib\site-packages\django\db\models\sql\query.py", line 1015, in solve_lookup_type
    _, field, _, lookup_parts = self.names_to_path(lookup_splitted, self.get_meta())
  File "C:\Users\huqiang\AppData\Local\Programs\Python\Python36\lib\site-packages\django\db\models\sql\query.py", line 1379, in names_to_path
    "Choices are: %s" % (name, ", ".join(available)))
django.core.exceptions.FieldError: Cannot resolve keyword 'name' into field. Choices are: Api_author, Api_include, Api_name, Api_request, Api_type, belong_module, belong_module_id, belong_project, create_time, id, update_time
2020-01-20 15:34:00,305 [django.request:118] [exception:handle_uncaught_exception] [ERROR]- Internal Server Error: /api/add_api/
Traceback (most recent call last):
  File "C:\Users\huqiang\AppData\Local\Programs\Python\Python36\lib\site-packages\django\core\handlers\exception.py", line 35, in inner
    response = get_response(request)
  File "C:\Users\huqiang\AppData\Local\Programs\Python\Python36\lib\site-packages\django\core\handlers\base.py", line 128, in _get_response
    response = self.process_exception_by_middleware(e, request)
  File "C:\Users\huqiang\AppData\Local\Programs\Python\Python36\lib\site-packages\django\core\handlers\base.py", line 126, in _get_response
    response = wrapped_callback(request, *callback_args, **callback_kwargs)
  File "D:/HttpRunnerManager\HttpRunnerManager\activator.py", line 15, in process
    result = fun(request, index) if index else fun(request)
  File "D:/HttpRunnerManager\ApiManager\views.py", line 39, in wrapper
    return func(request, *args, **kwargs)
  File "D:/HttpRunnerManager\ApiManager\views.py", line 194, in add_api
    msg = api_info_logic(**testcase_info)
  File "D:/HttpRunnerManager\ApiManager\utils\common.py", line 408, in api_info_logic
    return add_api_data(type, **kwargs)
  File "D:/HttpRunnerManager\ApiManager\utils\operation.py", line 191, in add_api_data
    if api_opt.get_api_name(name, module, project) < 1:
  File "D:/HttpRunnerManager\ApiManager\managers.py", line 176, in get_api_name
    return self.filter(belong_module__id=module_name).filter(name__exact=name).filter(
  File "C:\Users\huqiang\AppData\Local\Programs\Python\Python36\lib\site-packages\django\db\models\query.py", line 836, in filter
    return self._filter_or_exclude(False, *args, **kwargs)
  File "C:\Users\huqiang\AppData\Local\Programs\Python\Python36\lib\site-packages\django\db\models\query.py", line 854, in _filter_or_exclude
    clone.query.add_q(Q(*args, **kwargs))
  File "C:\Users\huqiang\AppData\Local\Programs\Python\Python36\lib\site-packages\django\db\models\sql\query.py", line 1253, in add_q
    clause, _ = self._add_q(q_object, self.used_aliases)
  File "C:\Users\huqiang\AppData\Local\Programs\Python\Python36\lib\site-packages\django\db\models\sql\query.py", line 1277, in _add_q
    split_subq=split_subq,
  File "C:\Users\huqiang\AppData\Local\Programs\Python\Python36\lib\site-packages\django\db\models\sql\query.py", line 1153, in build_filter
    lookups, parts, reffed_expression = self.solve_lookup_type(arg)
  File "C:\Users\huqiang\AppData\Local\Programs\Python\Python36\lib\site-packages\django\db\models\sql\query.py", line 1015, in solve_lookup_type
    _, field, _, lookup_parts = self.names_to_path(lookup_splitted, self.get_meta())
  File "C:\Users\huqiang\AppData\Local\Programs\Python\Python36\lib\site-packages\django\db\models\sql\query.py", line 1379, in names_to_path
    "Choices are: %s" % (name, ", ".join(available)))
django.core.exceptions.FieldError: Cannot resolve keyword 'name' into field. Choices are: Api_author, Api_include, Api_name, Api_request, Api_type, belong_module, belong_module_id, belong_project, create_time, id, update_time
2020-01-20 15:36:37,092 [django.request:118] [exception:handle_uncaught_exception] [ERROR]- Internal Server Error: /api/add_api/
Traceback (most recent call last):
  File "C:\Users\huqiang\AppData\Local\Programs\Python\Python36\lib\site-packages\django\core\handlers\exception.py", line 35, in inner
    response = get_response(request)
  File "C:\Users\huqiang\AppData\Local\Programs\Python\Python36\lib\site-packages\django\core\handlers\base.py", line 128, in _get_response
    response = self.process_exception_by_middleware(e, request)
  File "C:\Users\huqiang\AppData\Local\Programs\Python\Python36\lib\site-packages\django\core\handlers\base.py", line 126, in _get_response
    response = wrapped_callback(request, *callback_args, **callback_kwargs)
  File "D:/HttpRunnerManager\HttpRunnerManager\activator.py", line 15, in process
    result = fun(request, index) if index else fun(request)
  File "D:/HttpRunnerManager\ApiManager\views.py", line 39, in wrapper
    return func(request, *args, **kwargs)
  File "D:/HttpRunnerManager\ApiManager\views.py", line 194, in add_api
    msg = api_info_logic(**testcase_info)
  File "D:/HttpRunnerManager\ApiManager\utils\common.py", line 408, in api_info_logic
    return add_api_data(type, **kwargs)
  File "D:/HttpRunnerManager\ApiManager\utils\operation.py", line 191, in add_api_data
    if api_opt.get_api_name(name, module, project) < 1:
  File "D:/HttpRunnerManager\ApiManager\managers.py", line 176, in get_api_name
    return self.filter(belong_module__id=module_name).filter(name__exact=name).filter(
  File "C:\Users\huqiang\AppData\Local\Programs\Python\Python36\lib\site-packages\django\db\models\query.py", line 836, in filter
    return self._filter_or_exclude(False, *args, **kwargs)
  File "C:\Users\huqiang\AppData\Local\Programs\Python\Python36\lib\site-packages\django\db\models\query.py", line 854, in _filter_or_exclude
    clone.query.add_q(Q(*args, **kwargs))
  File "C:\Users\huqiang\AppData\Local\Programs\Python\Python36\lib\site-packages\django\db\models\sql\query.py", line 1253, in add_q
    clause, _ = self._add_q(q_object, self.used_aliases)
  File "C:\Users\huqiang\AppData\Local\Programs\Python\Python36\lib\site-packages\django\db\models\sql\query.py", line 1277, in _add_q
    split_subq=split_subq,
  File "C:\Users\huqiang\AppData\Local\Programs\Python\Python36\lib\site-packages\django\db\models\sql\query.py", line 1153, in build_filter
    lookups, parts, reffed_expression = self.solve_lookup_type(arg)
  File "C:\Users\huqiang\AppData\Local\Programs\Python\Python36\lib\site-packages\django\db\models\sql\query.py", line 1015, in solve_lookup_type
    _, field, _, lookup_parts = self.names_to_path(lookup_splitted, self.get_meta())
  File "C:\Users\huqiang\AppData\Local\Programs\Python\Python36\lib\site-packages\django\db\models\sql\query.py", line 1379, in names_to_path
    "Choices are: %s" % (name, ", ".join(available)))
django.core.exceptions.FieldError: Cannot resolve keyword 'name' into field. Choices are: Api_author, Api_include, Api_name, Api_request, Api_type, belong_module, belong_module_id, belong_project, create_time, id, update_time
2020-01-20 15:37:49,995 [django.request:93] [base:get_response] [WARNING]- Not Found: /
2020-01-20 15:38:13,248 [django.request:118] [exception:handle_uncaught_exception] [ERROR]- Internal Server Error: /api/add_api/
Traceback (most recent call last):
  File "C:\Users\huqiang\AppData\Local\Programs\Python\Python36\lib\site-packages\django\core\handlers\exception.py", line 35, in inner
    response = get_response(request)
  File "C:\Users\huqiang\AppData\Local\Programs\Python\Python36\lib\site-packages\django\core\handlers\base.py", line 128, in _get_response
    response = self.process_exception_by_middleware(e, request)
  File "C:\Users\huqiang\AppData\Local\Programs\Python\Python36\lib\site-packages\django\core\handlers\base.py", line 126, in _get_response
    response = wrapped_callback(request, *callback_args, **callback_kwargs)
  File "D:/HttpRunnerManager\HttpRunnerManager\activator.py", line 15, in process
    result = fun(request, index) if index else fun(request)
  File "D:/HttpRunnerManager\ApiManager\views.py", line 39, in wrapper
    return func(request, *args, **kwargs)
  File "D:/HttpRunnerManager\ApiManager\views.py", line 194, in add_api
    msg = api_info_logic(**testcase_info)
  File "D:/HttpRunnerManager\ApiManager\utils\common.py", line 408, in api_info_logic
    return add_api_data(type, **kwargs)
  File "D:/HttpRunnerManager\ApiManager\utils\operation.py", line 191, in add_api_data
    if api_opt.get_api_name(Api_name, module, project) < 1:
  File "D:/HttpRunnerManager\ApiManager\managers.py", line 176, in get_api_name
    return self.filter(belong_module__id=module_name).filter(name__exact=name).filter(
  File "C:\Users\huqiang\AppData\Local\Programs\Python\Python36\lib\site-packages\django\db\models\query.py", line 836, in filter
    return self._filter_or_exclude(False, *args, **kwargs)
  File "C:\Users\huqiang\AppData\Local\Programs\Python\Python36\lib\site-packages\django\db\models\query.py", line 854, in _filter_or_exclude
    clone.query.add_q(Q(*args, **kwargs))
  File "C:\Users\huqiang\AppData\Local\Programs\Python\Python36\lib\site-packages\django\db\models\sql\query.py", line 1253, in add_q
    clause, _ = self._add_q(q_object, self.used_aliases)
  File "C:\Users\huqiang\AppData\Local\Programs\Python\Python36\lib\site-packages\django\db\models\sql\query.py", line 1277, in _add_q
    split_subq=split_subq,
  File "C:\Users\huqiang\AppData\Local\Programs\Python\Python36\lib\site-packages\django\db\models\sql\query.py", line 1153, in build_filter
    lookups, parts, reffed_expression = self.solve_lookup_type(arg)
  File "C:\Users\huqiang\AppData\Local\Programs\Python\Python36\lib\site-packages\django\db\models\sql\query.py", line 1015, in solve_lookup_type
    _, field, _, lookup_parts = self.names_to_path(lookup_splitted, self.get_meta())
  File "C:\Users\huqiang\AppData\Local\Programs\Python\Python36\lib\site-packages\django\db\models\sql\query.py", line 1379, in names_to_path
    "Choices are: %s" % (name, ", ".join(available)))
django.core.exceptions.FieldError: Cannot resolve keyword 'name' into field. Choices are: Api_author, Api_include, Api_name, Api_request, Api_type, belong_module, belong_module_id, belong_project, create_time, id, update_time
2020-01-20 15:39:38,709 [HttpRunnerManager:193] [operation:add_api_data] [INFO]- 343434接口添加成功: {'test': {'request': {'url': '234', 'method': 'POST', 'data': {'222': '443'}}, 'name': '343434'}}
2020-01-20 15:39:42,868 [django.request:118] [exception:handle_uncaught_exception] [ERROR]- Internal Server Error: /api/api_list/1/
Traceback (most recent call last):
  File "C:\Users\huqiang\AppData\Local\Programs\Python\Python36\lib\site-packages\django\core\handlers\exception.py", line 35, in inner
    response = get_response(request)
  File "C:\Users\huqiang\AppData\Local\Programs\Python\Python36\lib\site-packages\django\core\handlers\base.py", line 128, in _get_response
    response = self.process_exception_by_middleware(e, request)
  File "C:\Users\huqiang\AppData\Local\Programs\Python\Python36\lib\site-packages\django\core\handlers\base.py", line 126, in _get_response
    response = wrapped_callback(request, *callback_args, **callback_kwargs)
  File "D:/HttpRunnerManager\HttpRunnerManager\activator.py", line 12, in process
    fun = getattr(view, fun)
AttributeError: module 'ApiManager.views' has no attribute 'api_list'
2020-01-20 15:52:56,237 [HttpRunnerManager:193] [operation:add_api_data] [INFO]- 1111111111接口添加成功: {'test': {'request': {'url': '11111', 'method': 'POST', 'data': {'1111': '111111'}}, 'name': '1111111111'}}
2020-01-20 15:56:07,793 [django.request:118] [exception:handle_uncaught_exception] [ERROR]- Internal Server Error: /api/test_api/1/
Traceback (most recent call last):
  File "C:\Users\huqiang\AppData\Local\Programs\Python\Python36\lib\site-packages\django\core\handlers\exception.py", line 35, in inner
    response = get_response(request)
  File "C:\Users\huqiang\AppData\Local\Programs\Python\Python36\lib\site-packages\django\core\handlers\base.py", line 128, in _get_response
    response = self.process_exception_by_middleware(e, request)
  File "C:\Users\huqiang\AppData\Local\Programs\Python\Python36\lib\site-packages\django\core\handlers\base.py", line 126, in _get_response
    response = wrapped_callback(request, *callback_args, **callback_kwargs)
  File "D:/HttpRunnerManager\HttpRunnerManager\activator.py", line 12, in process
    fun = getattr(view, fun)
AttributeError: module 'ApiManager.views' has no attribute 'test_api'
2020-01-20 15:59:34,892 [django.request:118] [exception:handle_uncaught_exception] [ERROR]- Internal Server Error: /api/test_api/1/
Traceback (most recent call last):
  File "C:\Users\huqiang\AppData\Local\Programs\Python\Python36\lib\site-packages\django\core\handlers\exception.py", line 35, in inner
    response = get_response(request)
  File "C:\Users\huqiang\AppData\Local\Programs\Python\Python36\lib\site-packages\django\core\handlers\base.py", line 128, in _get_response
    response = self.process_exception_by_middleware(e, request)
  File "C:\Users\huqiang\AppData\Local\Programs\Python\Python36\lib\site-packages\django\core\handlers\base.py", line 126, in _get_response
    response = wrapped_callback(request, *callback_args, **callback_kwargs)
  File "D:/HttpRunnerManager\HttpRunnerManager\activator.py", line 12, in process
    fun = getattr(view, fun)
AttributeError: module 'ApiManager.views' has no attribute 'test_api'
2020-01-20 16:04:34,546 [django.request:118] [exception:handle_uncaught_exception] [ERROR]- Internal Server Error: /api/test_api/1/
Traceback (most recent call last):
  File "C:\Users\huqiang\AppData\Local\Programs\Python\Python36\lib\site-packages\django\core\handlers\exception.py", line 35, in inner
    response = get_response(request)
  File "C:\Users\huqiang\AppData\Local\Programs\Python\Python36\lib\site-packages\django\core\handlers\base.py", line 128, in _get_response
    response = self.process_exception_by_middleware(e, request)
  File "C:\Users\huqiang\AppData\Local\Programs\Python\Python36\lib\site-packages\django\core\handlers\base.py", line 126, in _get_response
    response = wrapped_callback(request, *callback_args, **callback_kwargs)
  File "D:/HttpRunnerManager\HttpRunnerManager\activator.py", line 12, in process
    fun = getattr(view, fun)
AttributeError: module 'ApiManager.views' has no attribute 'test_api'
2020-01-20 16:05:36,520 [django.request:118] [exception:handle_uncaught_exception] [ERROR]- Internal Server Error: /api/api_list/1/
Traceback (most recent call last):
  File "C:\Users\huqiang\AppData\Local\Programs\Python\Python36\lib\site-packages\django\core\handlers\exception.py", line 35, in inner
    response = get_response(request)
  File "C:\Users\huqiang\AppData\Local\Programs\Python\Python36\lib\site-packages\django\core\handlers\base.py", line 128, in _get_response
    response = self.process_exception_by_middleware(e, request)
  File "C:\Users\huqiang\AppData\Local\Programs\Python\Python36\lib\site-packages\django\core\handlers\base.py", line 126, in _get_response
    response = wrapped_callback(request, *callback_args, **callback_kwargs)
  File "D:/HttpRunnerManager\HttpRunnerManager\activator.py", line 15, in process
    result = fun(request, index) if index else fun(request)
  File "D:/HttpRunnerManager\ApiManager\views.py", line 39, in wrapper
    return func(request, *args, **kwargs)
  File "D:/HttpRunnerManager\ApiManager\views.py", line 424, in api_list
    ApiInfo, filter_query, '/api/test_list/', id)
  File "D:/HttpRunnerManager\ApiManager\utils\pagination.py", line 137, in get_pager_info
    obj = obj.filter(type__exact=1) if url == '/api/test_list/' else obj.filter(type__exact=2)
  File "C:\Users\huqiang\AppData\Local\Programs\Python\Python36\lib\site-packages\django\db\models\manager.py", line 82, in manager_method
    return getattr(self.get_queryset(), name)(*args, **kwargs)
  File "C:\Users\huqiang\AppData\Local\Programs\Python\Python36\lib\site-packages\django\db\models\query.py", line 836, in filter
    return self._filter_or_exclude(False, *args, **kwargs)
  File "C:\Users\huqiang\AppData\Local\Programs\Python\Python36\lib\site-packages\django\db\models\query.py", line 854, in _filter_or_exclude
    clone.query.add_q(Q(*args, **kwargs))
  File "C:\Users\huqiang\AppData\Local\Programs\Python\Python36\lib\site-packages\django\db\models\sql\query.py", line 1253, in add_q
    clause, _ = self._add_q(q_object, self.used_aliases)
  File "C:\Users\huqiang\AppData\Local\Programs\Python\Python36\lib\site-packages\django\db\models\sql\query.py", line 1277, in _add_q
    split_subq=split_subq,
  File "C:\Users\huqiang\AppData\Local\Programs\Python\Python36\lib\site-packages\django\db\models\sql\query.py", line 1153, in build_filter
    lookups, parts, reffed_expression = self.solve_lookup_type(arg)
  File "C:\Users\huqiang\AppData\Local\Programs\Python\Python36\lib\site-packages\django\db\models\sql\query.py", line 1015, in solve_lookup_type
    _, field, _, lookup_parts = self.names_to_path(lookup_splitted, self.get_meta())
  File "C:\Users\huqiang\AppData\Local\Programs\Python\Python36\lib\site-packages\django\db\models\sql\query.py", line 1379, in names_to_path
    "Choices are: %s" % (name, ", ".join(available)))
django.core.exceptions.FieldError: Cannot resolve keyword 'type' into field. Choices are: Api_author, Api_include, Api_name, Api_request, Api_type, belong_module, belong_module_id, belong_project, create_time, id, update_time
2020-01-20 16:22:53,393 [django.request:118] [exception:handle_uncaught_exception] [ERROR]- Internal Server Error: /api/api_list/1/
Traceback (most recent call last):
  File "C:\Users\huqiang\AppData\Local\Programs\Python\Python36\lib\site-packages\django\core\handlers\exception.py", line 35, in inner
    response = get_response(request)
  File "C:\Users\huqiang\AppData\Local\Programs\Python\Python36\lib\site-packages\django\core\handlers\base.py", line 128, in _get_response
    response = self.process_exception_by_middleware(e, request)
  File "C:\Users\huqiang\AppData\Local\Programs\Python\Python36\lib\site-packages\django\core\handlers\base.py", line 126, in _get_response
    response = wrapped_callback(request, *callback_args, **callback_kwargs)
  File "D:/HttpRunnerManager\HttpRunnerManager\activator.py", line 15, in process
    result = fun(request, index) if index else fun(request)
  File "D:/HttpRunnerManager\ApiManager\views.py", line 39, in wrapper
    return func(request, *args, **kwargs)
  File "D:/HttpRunnerManager\ApiManager\views.py", line 433, in api_list
    return render_to_response('test_list.html', manage_info)
  File "C:\Users\huqiang\AppData\Local\Programs\Python\Python36\lib\site-packages\django\shortcuts.py", line 27, in render_to_response
    content = loader.render_to_string(template_name, context, using=using)
  File "C:\Users\huqiang\AppData\Local\Programs\Python\Python36\lib\site-packages\django\template\loader.py", line 62, in render_to_string
    return template.render(context, request)
  File "C:\Users\huqiang\AppData\Local\Programs\Python\Python36\lib\site-packages\django\template\backends\django.py", line 61, in render
    return self.template.render(context)
  File "C:\Users\huqiang\AppData\Local\Programs\Python\Python36\lib\site-packages\django\template\base.py", line 175, in render
    return self._render(context)
  File "C:\Users\huqiang\AppData\Local\Programs\Python\Python36\lib\site-packages\django\template\base.py", line 167, in _render
    return self.nodelist.render(context)
  File "C:\Users\huqiang\AppData\Local\Programs\Python\Python36\lib\site-packages\django\template\base.py", line 943, in render
    bit = node.render_annotated(context)
  File "C:\Users\huqiang\AppData\Local\Programs\Python\Python36\lib\site-packages\django\template\base.py", line 910, in render_annotated
    return self.render(context)
  File "C:\Users\huqiang\AppData\Local\Programs\Python\Python36\lib\site-packages\django\template\loader_tags.py", line 155, in render
    return compiled_parent._render(context)
  File "C:\Users\huqiang\AppData\Local\Programs\Python\Python36\lib\site-packages\django\template\base.py", line 167, in _render
    return self.nodelist.render(context)
  File "C:\Users\huqiang\AppData\Local\Programs\Python\Python36\lib\site-packages\django\template\base.py", line 943, in render
    bit = node.render_annotated(context)
  File "C:\Users\huqiang\AppData\Local\Programs\Python\Python36\lib\site-packages\django\template\base.py", line 910, in render_annotated
    return self.render(context)
  File "C:\Users\huqiang\AppData\Local\Programs\Python\Python36\lib\site-packages\django\template\loader_tags.py", line 67, in render
    result = block.nodelist.render(context)
  File "C:\Users\huqiang\AppData\Local\Programs\Python\Python36\lib\site-packages\django\template\base.py", line 943, in render
    bit = node.render_annotated(context)
  File "C:\Users\huqiang\AppData\Local\Programs\Python\Python36\lib\site-packages\django\template\base.py", line 910, in render_annotated
    return self.render(context)
  File "C:\Users\huqiang\AppData\Local\Programs\Python\Python36\lib\site-packages\django\template\defaulttags.py", line 211, in render
    nodelist.append(node.render_annotated(context))
  File "C:\Users\huqiang\AppData\Local\Programs\Python\Python36\lib\site-packages\django\template\base.py", line 910, in render_annotated
    return self.render(context)
  File "C:\Users\huqiang\AppData\Local\Programs\Python\Python36\lib\site-packages\django\template\defaulttags.py", line 161, in render
    values = self.sequence.resolve(context, True)
  File "C:\Users\huqiang\AppData\Local\Programs\Python\Python36\lib\site-packages\django\template\base.py", line 703, in resolve
    new_obj = func(obj, *arg_vals)
  File "D:/HttpRunnerManager\ApiManager\templatetags\custom_tags.py", line 27, in convert_eval
    return update_include(eval(value))
TypeError: eval() arg 1 must be a string, bytes or code object
2020-01-20 16:25:13,760 [django.request:118] [exception:handle_uncaught_exception] [ERROR]- Internal Server Error: /api/api_list/1/
Traceback (most recent call last):
  File "C:\Users\huqiang\AppData\Local\Programs\Python\Python36\lib\site-packages\django\core\handlers\exception.py", line 35, in inner
    response = get_response(request)
  File "C:\Users\huqiang\AppData\Local\Programs\Python\Python36\lib\site-packages\django\core\handlers\base.py", line 128, in _get_response
    response = self.process_exception_by_middleware(e, request)
  File "C:\Users\huqiang\AppData\Local\Programs\Python\Python36\lib\site-packages\django\core\handlers\base.py", line 126, in _get_response
    response = wrapped_callback(request, *callback_args, **callback_kwargs)
  File "D:/HttpRunnerManager\HttpRunnerManager\activator.py", line 15, in process
    result = fun(request, index) if index else fun(request)
  File "D:/HttpRunnerManager\ApiManager\views.py", line 39, in wrapper
    return func(request, *args, **kwargs)
  File "D:/HttpRunnerManager\ApiManager\views.py", line 433, in api_list
    return render_to_response('api_list.html', manage_info)
  File "C:\Users\huqiang\AppData\Local\Programs\Python\Python36\lib\site-packages\django\shortcuts.py", line 27, in render_to_response
    content = loader.render_to_string(template_name, context, using=using)
  File "C:\Users\huqiang\AppData\Local\Programs\Python\Python36\lib\site-packages\django\template\loader.py", line 62, in render_to_string
    return template.render(context, request)
  File "C:\Users\huqiang\AppData\Local\Programs\Python\Python36\lib\site-packages\django\template\backends\django.py", line 61, in render
    return self.template.render(context)
  File "C:\Users\huqiang\AppData\Local\Programs\Python\Python36\lib\site-packages\django\template\base.py", line 175, in render
    return self._render(context)
  File "C:\Users\huqiang\AppData\Local\Programs\Python\Python36\lib\site-packages\django\template\base.py", line 167, in _render
    return self.nodelist.render(context)
  File "C:\Users\huqiang\AppData\Local\Programs\Python\Python36\lib\site-packages\django\template\base.py", line 943, in render
    bit = node.render_annotated(context)
  File "C:\Users\huqiang\AppData\Local\Programs\Python\Python36\lib\site-packages\django\template\base.py", line 910, in render_annotated
    return self.render(context)
  File "C:\Users\huqiang\AppData\Local\Programs\Python\Python36\lib\site-packages\django\template\loader_tags.py", line 155, in render
    return compiled_parent._render(context)
  File "C:\Users\huqiang\AppData\Local\Programs\Python\Python36\lib\site-packages\django\template\base.py", line 167, in _render
    return self.nodelist.render(context)
  File "C:\Users\huqiang\AppData\Local\Programs\Python\Python36\lib\site-packages\django\template\base.py", line 943, in render
    bit = node.render_annotated(context)
  File "C:\Users\huqiang\AppData\Local\Programs\Python\Python36\lib\site-packages\django\template\base.py", line 910, in render_annotated
    return self.render(context)
  File "C:\Users\huqiang\AppData\Local\Programs\Python\Python36\lib\site-packages\django\template\loader_tags.py", line 67, in render
    result = block.nodelist.render(context)
  File "C:\Users\huqiang\AppData\Local\Programs\Python\Python36\lib\site-packages\django\template\base.py", line 943, in render
    bit = node.render_annotated(context)
  File "C:\Users\huqiang\AppData\Local\Programs\Python\Python36\lib\site-packages\django\template\base.py", line 910, in render_annotated
    return self.render(context)
  File "C:\Users\huqiang\AppData\Local\Programs\Python\Python36\lib\site-packages\django\template\defaulttags.py", line 211, in render
    nodelist.append(node.render_annotated(context))
  File "C:\Users\huqiang\AppData\Local\Programs\Python\Python36\lib\site-packages\django\template\base.py", line 910, in render_annotated
    return self.render(context)
  File "C:\Users\huqiang\AppData\Local\Programs\Python\Python36\lib\site-packages\django\template\defaulttags.py", line 161, in render
    values = self.sequence.resolve(context, True)
  File "C:\Users\huqiang\AppData\Local\Programs\Python\Python36\lib\site-packages\django\template\base.py", line 703, in resolve
    new_obj = func(obj, *arg_vals)
  File "D:/HttpRunnerManager\ApiManager\templatetags\custom_tags.py", line 27, in convert_eval
    return update_include(eval(value))
TypeError: eval() arg 1 must be a string, bytes or code object
2020-01-20 16:28:55,475 [django.request:118] [exception:handle_uncaught_exception] [ERROR]- Internal Server Error: /api/api_list/1/
Traceback (most recent call last):
  File "C:\Users\huqiang\AppData\Local\Programs\Python\Python36\lib\site-packages\django\core\handlers\exception.py", line 35, in inner
    response = get_response(request)
  File "C:\Users\huqiang\AppData\Local\Programs\Python\Python36\lib\site-packages\django\core\handlers\base.py", line 128, in _get_response
    response = self.process_exception_by_middleware(e, request)
  File "C:\Users\huqiang\AppData\Local\Programs\Python\Python36\lib\site-packages\django\core\handlers\base.py", line 126, in _get_response
    response = wrapped_callback(request, *callback_args, **callback_kwargs)
  File "D:/HttpRunnerManager\HttpRunnerManager\activator.py", line 15, in process
    result = fun(request, index) if index else fun(request)
  File "D:/HttpRunnerManager\ApiManager\views.py", line 39, in wrapper
    return func(request, *args, **kwargs)
  File "D:/HttpRunnerManager\ApiManager\views.py", line 433, in api_list
    return render_to_response('api_list.html', manage_info)
  File "C:\Users\huqiang\AppData\Local\Programs\Python\Python36\lib\site-packages\django\shortcuts.py", line 27, in render_to_response
    content = loader.render_to_string(template_name, context, using=using)
  File "C:\Users\huqiang\AppData\Local\Programs\Python\Python36\lib\site-packages\django\template\loader.py", line 62, in render_to_string
    return template.render(context, request)
  File "C:\Users\huqiang\AppData\Local\Programs\Python\Python36\lib\site-packages\django\template\backends\django.py", line 61, in render
    return self.template.render(context)
  File "C:\Users\huqiang\AppData\Local\Programs\Python\Python36\lib\site-packages\django\template\base.py", line 175, in render
    return self._render(context)
  File "C:\Users\huqiang\AppData\Local\Programs\Python\Python36\lib\site-packages\django\template\base.py", line 167, in _render
    return self.nodelist.render(context)
  File "C:\Users\huqiang\AppData\Local\Programs\Python\Python36\lib\site-packages\django\template\base.py", line 943, in render
    bit = node.render_annotated(context)
  File "C:\Users\huqiang\AppData\Local\Programs\Python\Python36\lib\site-packages\django\template\base.py", line 910, in render_annotated
    return self.render(context)
  File "C:\Users\huqiang\AppData\Local\Programs\Python\Python36\lib\site-packages\django\template\loader_tags.py", line 155, in render
    return compiled_parent._render(context)
  File "C:\Users\huqiang\AppData\Local\Programs\Python\Python36\lib\site-packages\django\template\base.py", line 167, in _render
    return self.nodelist.render(context)
  File "C:\Users\huqiang\AppData\Local\Programs\Python\Python36\lib\site-packages\django\template\base.py", line 943, in render
    bit = node.render_annotated(context)
  File "C:\Users\huqiang\AppData\Local\Programs\Python\Python36\lib\site-packages\django\template\base.py", line 910, in render_annotated
    return self.render(context)
  File "C:\Users\huqiang\AppData\Local\Programs\Python\Python36\lib\site-packages\django\template\loader_tags.py", line 67, in render
    result = block.nodelist.render(context)
  File "C:\Users\huqiang\AppData\Local\Programs\Python\Python36\lib\site-packages\django\template\base.py", line 943, in render
    bit = node.render_annotated(context)
  File "C:\Users\huqiang\AppData\Local\Programs\Python\Python36\lib\site-packages\django\template\base.py", line 910, in render_annotated
    return self.render(context)
  File "C:\Users\huqiang\AppData\Local\Programs\Python\Python36\lib\site-packages\django\template\defaulttags.py", line 211, in render
    nodelist.append(node.render_annotated(context))
  File "C:\Users\huqiang\AppData\Local\Programs\Python\Python36\lib\site-packages\django\template\base.py", line 910, in render_annotated
    return self.render(context)
  File "C:\Users\huqiang\AppData\Local\Programs\Python\Python36\lib\site-packages\django\template\defaulttags.py", line 161, in render
    values = self.sequence.resolve(context, True)
  File "C:\Users\huqiang\AppData\Local\Programs\Python\Python36\lib\site-packages\django\template\base.py", line 703, in resolve
    new_obj = func(obj, *arg_vals)
  File "D:/HttpRunnerManager\ApiManager\templatetags\custom_tags.py", line 27, in convert_eval
    return update_include(eval(value))
TypeError: eval() arg 1 must be a string, bytes or code object
2020-01-20 16:28:55,774 [django.request:118] [exception:handle_uncaught_exception] [ERROR]- Internal Server Error: /api/api_list/1/
Traceback (most recent call last):
  File "C:\Users\huqiang\AppData\Local\Programs\Python\Python36\lib\site-packages\django\core\handlers\exception.py", line 35, in inner
    response = get_response(request)
  File "C:\Users\huqiang\AppData\Local\Programs\Python\Python36\lib\site-packages\django\core\handlers\base.py", line 128, in _get_response
    response = self.process_exception_by_middleware(e, request)
  File "C:\Users\huqiang\AppData\Local\Programs\Python\Python36\lib\site-packages\django\core\handlers\base.py", line 126, in _get_response
    response = wrapped_callback(request, *callback_args, **callback_kwargs)
  File "D:/HttpRunnerManager\HttpRunnerManager\activator.py", line 15, in process
    result = fun(request, index) if index else fun(request)
  File "D:/HttpRunnerManager\ApiManager\views.py", line 39, in wrapper
    return func(request, *args, **kwargs)
  File "D:/HttpRunnerManager\ApiManager\views.py", line 433, in api_list
    return render_to_response('api_list.html', manage_info)
  File "C:\Users\huqiang\AppData\Local\Programs\Python\Python36\lib\site-packages\django\shortcuts.py", line 27, in render_to_response
    content = loader.render_to_string(template_name, context, using=using)
  File "C:\Users\huqiang\AppData\Local\Programs\Python\Python36\lib\site-packages\django\template\loader.py", line 62, in render_to_string
    return template.render(context, request)
  File "C:\Users\huqiang\AppData\Local\Programs\Python\Python36\lib\site-packages\django\template\backends\django.py", line 61, in render
    return self.template.render(context)
  File "C:\Users\huqiang\AppData\Local\Programs\Python\Python36\lib\site-packages\django\template\base.py", line 175, in render
    return self._render(context)
  File "C:\Users\huqiang\AppData\Local\Programs\Python\Python36\lib\site-packages\django\template\base.py", line 167, in _render
    return self.nodelist.render(context)
  File "C:\Users\huqiang\AppData\Local\Programs\Python\Python36\lib\site-packages\django\template\base.py", line 943, in render
    bit = node.render_annotated(context)
  File "C:\Users\huqiang\AppData\Local\Programs\Python\Python36\lib\site-packages\django\template\base.py", line 910, in render_annotated
    return self.render(context)
  File "C:\Users\huqiang\AppData\Local\Programs\Python\Python36\lib\site-packages\django\template\loader_tags.py", line 155, in render
    return compiled_parent._render(context)
  File "C:\Users\huqiang\AppData\Local\Programs\Python\Python36\lib\site-packages\django\template\base.py", line 167, in _render
    return self.nodelist.render(context)
  File "C:\Users\huqiang\AppData\Local\Programs\Python\Python36\lib\site-packages\django\template\base.py", line 943, in render
    bit = node.render_annotated(context)
  File "C:\Users\huqiang\AppData\Local\Programs\Python\Python36\lib\site-packages\django\template\base.py", line 910, in render_annotated
    return self.render(context)
  File "C:\Users\huqiang\AppData\Local\Programs\Python\Python36\lib\site-packages\django\template\loader_tags.py", line 67, in render
    result = block.nodelist.render(context)
  File "C:\Users\huqiang\AppData\Local\Programs\Python\Python36\lib\site-packages\django\template\base.py", line 943, in render
    bit = node.render_annotated(context)
  File "C:\Users\huqiang\AppData\Local\Programs\Python\Python36\lib\site-packages\django\template\base.py", line 910, in render_annotated
    return self.render(context)
  File "C:\Users\huqiang\AppData\Local\Programs\Python\Python36\lib\site-packages\django\template\defaulttags.py", line 211, in render
    nodelist.append(node.render_annotated(context))
  File "C:\Users\huqiang\AppData\Local\Programs\Python\Python36\lib\site-packages\django\template\base.py", line 910, in render_annotated
    return self.render(context)
  File "C:\Users\huqiang\AppData\Local\Programs\Python\Python36\lib\site-packages\django\template\defaulttags.py", line 161, in render
    values = self.sequence.resolve(context, True)
  File "C:\Users\huqiang\AppData\Local\Programs\Python\Python36\lib\site-packages\django\template\base.py", line 703, in resolve
    new_obj = func(obj, *arg_vals)
  File "D:/HttpRunnerManager\ApiManager\templatetags\custom_tags.py", line 27, in convert_eval
    return update_include(eval(value))
TypeError: eval() arg 1 must be a string, bytes or code object
2020-01-20 16:30:55,925 [django.request:118] [exception:handle_uncaught_exception] [ERROR]- Internal Server Error: /api/api_list/1/
Traceback (most recent call last):
  File "C:\Users\huqiang\AppData\Local\Programs\Python\Python36\lib\site-packages\django\core\handlers\exception.py", line 35, in inner
    response = get_response(request)
  File "C:\Users\huqiang\AppData\Local\Programs\Python\Python36\lib\site-packages\django\core\handlers\base.py", line 128, in _get_response
    response = self.process_exception_by_middleware(e, request)
  File "C:\Users\huqiang\AppData\Local\Programs\Python\Python36\lib\site-packages\django\core\handlers\base.py", line 126, in _get_response
    response = wrapped_callback(request, *callback_args, **callback_kwargs)
  File "D:/HttpRunnerManager\HttpRunnerManager\activator.py", line 15, in process
    result = fun(request, index) if index else fun(request)
  File "D:/HttpRunnerManager\ApiManager\views.py", line 39, in wrapper
    return func(request, *args, **kwargs)
  File "D:/HttpRunnerManager\ApiManager\views.py", line 433, in api_list
    return render_to_response('api_list.html', manage_info)
  File "C:\Users\huqiang\AppData\Local\Programs\Python\Python36\lib\site-packages\django\shortcuts.py", line 27, in render_to_response
    content = loader.render_to_string(template_name, context, using=using)
  File "C:\Users\huqiang\AppData\Local\Programs\Python\Python36\lib\site-packages\django\template\loader.py", line 62, in render_to_string
    return template.render(context, request)
  File "C:\Users\huqiang\AppData\Local\Programs\Python\Python36\lib\site-packages\django\template\backends\django.py", line 61, in render
    return self.template.render(context)
  File "C:\Users\huqiang\AppData\Local\Programs\Python\Python36\lib\site-packages\django\template\base.py", line 175, in render
    return self._render(context)
  File "C:\Users\huqiang\AppData\Local\Programs\Python\Python36\lib\site-packages\django\template\base.py", line 167, in _render
    return self.nodelist.render(context)
  File "C:\Users\huqiang\AppData\Local\Programs\Python\Python36\lib\site-packages\django\template\base.py", line 943, in render
    bit = node.render_annotated(context)
  File "C:\Users\huqiang\AppData\Local\Programs\Python\Python36\lib\site-packages\django\template\base.py", line 910, in render_annotated
    return self.render(context)
  File "C:\Users\huqiang\AppData\Local\Programs\Python\Python36\lib\site-packages\django\template\loader_tags.py", line 155, in render
    return compiled_parent._render(context)
  File "C:\Users\huqiang\AppData\Local\Programs\Python\Python36\lib\site-packages\django\template\base.py", line 167, in _render
    return self.nodelist.render(context)
  File "C:\Users\huqiang\AppData\Local\Programs\Python\Python36\lib\site-packages\django\template\base.py", line 943, in render
    bit = node.render_annotated(context)
  File "C:\Users\huqiang\AppData\Local\Programs\Python\Python36\lib\site-packages\django\template\base.py", line 910, in render_annotated
    return self.render(context)
  File "C:\Users\huqiang\AppData\Local\Programs\Python\Python36\lib\site-packages\django\template\loader_tags.py", line 67, in render
    result = block.nodelist.render(context)
  File "C:\Users\huqiang\AppData\Local\Programs\Python\Python36\lib\site-packages\django\template\base.py", line 943, in render
    bit = node.render_annotated(context)
  File "C:\Users\huqiang\AppData\Local\Programs\Python\Python36\lib\site-packages\django\template\base.py", line 910, in render_annotated
    return self.render(context)
  File "C:\Users\huqiang\AppData\Local\Programs\Python\Python36\lib\site-packages\django\template\defaulttags.py", line 211, in render
    nodelist.append(node.render_annotated(context))
  File "C:\Users\huqiang\AppData\Local\Programs\Python\Python36\lib\site-packages\django\template\base.py", line 910, in render_annotated
    return self.render(context)
  File "C:\Users\huqiang\AppData\Local\Programs\Python\Python36\lib\site-packages\django\template\defaulttags.py", line 161, in render
    values = self.sequence.resolve(context, True)
  File "C:\Users\huqiang\AppData\Local\Programs\Python\Python36\lib\site-packages\django\template\base.py", line 703, in resolve
    new_obj = func(obj, *arg_vals)
  File "D:/HttpRunnerManager\ApiManager\templatetags\custom_tags.py", line 27, in convert_eval
    return update_include(eval(value))
TypeError: eval() arg 1 must be a string, bytes or code object
2020-01-20 16:30:58,156 [django.request:118] [exception:handle_uncaught_exception] [ERROR]- Internal Server Error: /api/api_list/1/
Traceback (most recent call last):
  File "C:\Users\huqiang\AppData\Local\Programs\Python\Python36\lib\site-packages\django\core\handlers\exception.py", line 35, in inner
    response = get_response(request)
  File "C:\Users\huqiang\AppData\Local\Programs\Python\Python36\lib\site-packages\django\core\handlers\base.py", line 128, in _get_response
    response = self.process_exception_by_middleware(e, request)
  File "C:\Users\huqiang\AppData\Local\Programs\Python\Python36\lib\site-packages\django\core\handlers\base.py", line 126, in _get_response
    response = wrapped_callback(request, *callback_args, **callback_kwargs)
  File "D:/HttpRunnerManager\HttpRunnerManager\activator.py", line 15, in process
    result = fun(request, index) if index else fun(request)
  File "D:/HttpRunnerManager\ApiManager\views.py", line 39, in wrapper
    return func(request, *args, **kwargs)
  File "D:/HttpRunnerManager\ApiManager\views.py", line 433, in api_list
    return render_to_response('api_list.html', manage_info)
  File "C:\Users\huqiang\AppData\Local\Programs\Python\Python36\lib\site-packages\django\shortcuts.py", line 27, in render_to_response
    content = loader.render_to_string(template_name, context, using=using)
  File "C:\Users\huqiang\AppData\Local\Programs\Python\Python36\lib\site-packages\django\template\loader.py", line 62, in render_to_string
    return template.render(context, request)
  File "C:\Users\huqiang\AppData\Local\Programs\Python\Python36\lib\site-packages\django\template\backends\django.py", line 61, in render
    return self.template.render(context)
  File "C:\Users\huqiang\AppData\Local\Programs\Python\Python36\lib\site-packages\django\template\base.py", line 175, in render
    return self._render(context)
  File "C:\Users\huqiang\AppData\Local\Programs\Python\Python36\lib\site-packages\django\template\base.py", line 167, in _render
    return self.nodelist.render(context)
  File "C:\Users\huqiang\AppData\Local\Programs\Python\Python36\lib\site-packages\django\template\base.py", line 943, in render
    bit = node.render_annotated(context)
  File "C:\Users\huqiang\AppData\Local\Programs\Python\Python36\lib\site-packages\django\template\base.py", line 910, in render_annotated
    return self.render(context)
  File "C:\Users\huqiang\AppData\Local\Programs\Python\Python36\lib\site-packages\django\template\loader_tags.py", line 155, in render
    return compiled_parent._render(context)
  File "C:\Users\huqiang\AppData\Local\Programs\Python\Python36\lib\site-packages\django\template\base.py", line 167, in _render
    return self.nodelist.render(context)
  File "C:\Users\huqiang\AppData\Local\Programs\Python\Python36\lib\site-packages\django\template\base.py", line 943, in render
    bit = node.render_annotated(context)
  File "C:\Users\huqiang\AppData\Local\Programs\Python\Python36\lib\site-packages\django\template\base.py", line 910, in render_annotated
    return self.render(context)
  File "C:\Users\huqiang\AppData\Local\Programs\Python\Python36\lib\site-packages\django\template\loader_tags.py", line 67, in render
    result = block.nodelist.render(context)
  File "C:\Users\huqiang\AppData\Local\Programs\Python\Python36\lib\site-packages\django\template\base.py", line 943, in render
    bit = node.render_annotated(context)
  File "C:\Users\huqiang\AppData\Local\Programs\Python\Python36\lib\site-packages\django\template\base.py", line 910, in render_annotated
    return self.render(context)
  File "C:\Users\huqiang\AppData\Local\Programs\Python\Python36\lib\site-packages\django\template\defaulttags.py", line 211, in render
    nodelist.append(node.render_annotated(context))
  File "C:\Users\huqiang\AppData\Local\Programs\Python\Python36\lib\site-packages\django\template\base.py", line 910, in render_annotated
    return self.render(context)
  File "C:\Users\huqiang\AppData\Local\Programs\Python\Python36\lib\site-packages\django\template\defaulttags.py", line 161, in render
    values = self.sequence.resolve(context, True)
  File "C:\Users\huqiang\AppData\Local\Programs\Python\Python36\lib\site-packages\django\template\base.py", line 703, in resolve
    new_obj = func(obj, *arg_vals)
  File "D:/HttpRunnerManager\ApiManager\templatetags\custom_tags.py", line 27, in convert_eval
    return update_include(eval(value))
TypeError: eval() arg 1 must be a string, bytes or code object
2020-01-20 16:31:04,182 [django.request:118] [exception:handle_uncaught_exception] [ERROR]- Internal Server Error: /api/api_list/1/
Traceback (most recent call last):
  File "C:\Users\huqiang\AppData\Local\Programs\Python\Python36\lib\site-packages\django\core\handlers\exception.py", line 35, in inner
    response = get_response(request)
  File "C:\Users\huqiang\AppData\Local\Programs\Python\Python36\lib\site-packages\django\core\handlers\base.py", line 128, in _get_response
    response = self.process_exception_by_middleware(e, request)
  File "C:\Users\huqiang\AppData\Local\Programs\Python\Python36\lib\site-packages\django\core\handlers\base.py", line 126, in _get_response
    response = wrapped_callback(request, *callback_args, **callback_kwargs)
  File "D:/HttpRunnerManager\HttpRunnerManager\activator.py", line 15, in process
    result = fun(request, index) if index else fun(request)
  File "D:/HttpRunnerManager\ApiManager\views.py", line 39, in wrapper
    return func(request, *args, **kwargs)
  File "D:/HttpRunnerManager\ApiManager\views.py", line 433, in api_list
    return render_to_response('api_list.html', manage_info)
  File "C:\Users\huqiang\AppData\Local\Programs\Python\Python36\lib\site-packages\django\shortcuts.py", line 27, in render_to_response
    content = loader.render_to_string(template_name, context, using=using)
  File "C:\Users\huqiang\AppData\Local\Programs\Python\Python36\lib\site-packages\django\template\loader.py", line 62, in render_to_string
    return template.render(context, request)
  File "C:\Users\huqiang\AppData\Local\Programs\Python\Python36\lib\site-packages\django\template\backends\django.py", line 61, in render
    return self.template.render(context)
  File "C:\Users\huqiang\AppData\Local\Programs\Python\Python36\lib\site-packages\django\template\base.py", line 175, in render
    return self._render(context)
  File "C:\Users\huqiang\AppData\Local\Programs\Python\Python36\lib\site-packages\django\template\base.py", line 167, in _render
    return self.nodelist.render(context)
  File "C:\Users\huqiang\AppData\Local\Programs\Python\Python36\lib\site-packages\django\template\base.py", line 943, in render
    bit = node.render_annotated(context)
  File "C:\Users\huqiang\AppData\Local\Programs\Python\Python36\lib\site-packages\django\template\base.py", line 910, in render_annotated
    return self.render(context)
  File "C:\Users\huqiang\AppData\Local\Programs\Python\Python36\lib\site-packages\django\template\loader_tags.py", line 155, in render
    return compiled_parent._render(context)
  File "C:\Users\huqiang\AppData\Local\Programs\Python\Python36\lib\site-packages\django\template\base.py", line 167, in _render
    return self.nodelist.render(context)
  File "C:\Users\huqiang\AppData\Local\Programs\Python\Python36\lib\site-packages\django\template\base.py", line 943, in render
    bit = node.render_annotated(context)
  File "C:\Users\huqiang\AppData\Local\Programs\Python\Python36\lib\site-packages\django\template\base.py", line 910, in render_annotated
    return self.render(context)
  File "C:\Users\huqiang\AppData\Local\Programs\Python\Python36\lib\site-packages\django\template\loader_tags.py", line 67, in render
    result = block.nodelist.render(context)
  File "C:\Users\huqiang\AppData\Local\Programs\Python\Python36\lib\site-packages\django\template\base.py", line 943, in render
    bit = node.render_annotated(context)
  File "C:\Users\huqiang\AppData\Local\Programs\Python\Python36\lib\site-packages\django\template\base.py", line 910, in render_annotated
    return self.render(context)
  File "C:\Users\huqiang\AppData\Local\Programs\Python\Python36\lib\site-packages\django\template\defaulttags.py", line 211, in render
    nodelist.append(node.render_annotated(context))
  File "C:\Users\huqiang\AppData\Local\Programs\Python\Python36\lib\site-packages\django\template\base.py", line 910, in render_annotated
    return self.render(context)
  File "C:\Users\huqiang\AppData\Local\Programs\Python\Python36\lib\site-packages\django\template\defaulttags.py", line 161, in render
    values = self.sequence.resolve(context, True)
  File "C:\Users\huqiang\AppData\Local\Programs\Python\Python36\lib\site-packages\django\template\base.py", line 703, in resolve
    new_obj = func(obj, *arg_vals)
  File "D:/HttpRunnerManager\ApiManager\templatetags\custom_tags.py", line 27, in convert_eval
    return update_include(eval(value))
TypeError: eval() arg 1 must be a string, bytes or code object
2020-01-20 16:31:15,842 [django.request:118] [exception:handle_uncaught_exception] [ERROR]- Internal Server Error: /api/api_list/1/
Traceback (most recent call last):
  File "C:\Users\huqiang\AppData\Local\Programs\Python\Python36\lib\site-packages\django\core\handlers\exception.py", line 35, in inner
    response = get_response(request)
  File "C:\Users\huqiang\AppData\Local\Programs\Python\Python36\lib\site-packages\django\core\handlers\base.py", line 128, in _get_response
    response = self.process_exception_by_middleware(e, request)
  File "C:\Users\huqiang\AppData\Local\Programs\Python\Python36\lib\site-packages\django\core\handlers\base.py", line 126, in _get_response
    response = wrapped_callback(request, *callback_args, **callback_kwargs)
  File "D:/HttpRunnerManager\HttpRunnerManager\activator.py", line 15, in process
    result = fun(request, index) if index else fun(request)
  File "D:/HttpRunnerManager\ApiManager\views.py", line 39, in wrapper
    return func(request, *args, **kwargs)
  File "D:/HttpRunnerManager\ApiManager\views.py", line 433, in api_list
    return render_to_response('api_list.html', manage_info)
  File "C:\Users\huqiang\AppData\Local\Programs\Python\Python36\lib\site-packages\django\shortcuts.py", line 27, in render_to_response
    content = loader.render_to_string(template_name, context, using=using)
  File "C:\Users\huqiang\AppData\Local\Programs\Python\Python36\lib\site-packages\django\template\loader.py", line 62, in render_to_string
    return template.render(context, request)
  File "C:\Users\huqiang\AppData\Local\Programs\Python\Python36\lib\site-packages\django\template\backends\django.py", line 61, in render
    return self.template.render(context)
  File "C:\Users\huqiang\AppData\Local\Programs\Python\Python36\lib\site-packages\django\template\base.py", line 175, in render
    return self._render(context)
  File "C:\Users\huqiang\AppData\Local\Programs\Python\Python36\lib\site-packages\django\template\base.py", line 167, in _render
    return self.nodelist.render(context)
  File "C:\Users\huqiang\AppData\Local\Programs\Python\Python36\lib\site-packages\django\template\base.py", line 943, in render
    bit = node.render_annotated(context)
  File "C:\Users\huqiang\AppData\Local\Programs\Python\Python36\lib\site-packages\django\template\base.py", line 910, in render_annotated
    return self.render(context)
  File "C:\Users\huqiang\AppData\Local\Programs\Python\Python36\lib\site-packages\django\template\loader_tags.py", line 155, in render
    return compiled_parent._render(context)
  File "C:\Users\huqiang\AppData\Local\Programs\Python\Python36\lib\site-packages\django\template\base.py", line 167, in _render
    return self.nodelist.render(context)
  File "C:\Users\huqiang\AppData\Local\Programs\Python\Python36\lib\site-packages\django\template\base.py", line 943, in render
    bit = node.render_annotated(context)
  File "C:\Users\huqiang\AppData\Local\Programs\Python\Python36\lib\site-packages\django\template\base.py", line 910, in render_annotated
    return self.render(context)
  File "C:\Users\huqiang\AppData\Local\Programs\Python\Python36\lib\site-packages\django\template\loader_tags.py", line 67, in render
    result = block.nodelist.render(context)
  File "C:\Users\huqiang\AppData\Local\Programs\Python\Python36\lib\site-packages\django\template\base.py", line 943, in render
    bit = node.render_annotated(context)
  File "C:\Users\huqiang\AppData\Local\Programs\Python\Python36\lib\site-packages\django\template\base.py", line 910, in render_annotated
    return self.render(context)
  File "C:\Users\huqiang\AppData\Local\Programs\Python\Python36\lib\site-packages\django\template\defaulttags.py", line 211, in render
    nodelist.append(node.render_annotated(context))
  File "C:\Users\huqiang\AppData\Local\Programs\Python\Python36\lib\site-packages\django\template\base.py", line 910, in render_annotated
    return self.render(context)
  File "C:\Users\huqiang\AppData\Local\Programs\Python\Python36\lib\site-packages\django\template\defaulttags.py", line 161, in render
    values = self.sequence.resolve(context, True)
  File "C:\Users\huqiang\AppData\Local\Programs\Python\Python36\lib\site-packages\django\template\base.py", line 703, in resolve
    new_obj = func(obj, *arg_vals)
  File "D:/HttpRunnerManager\ApiManager\templatetags\custom_tags.py", line 27, in convert_eval
    return update_include(eval(value))
TypeError: eval() arg 1 must be a string, bytes or code object
2020-01-20 16:32:27,331 [django.request:118] [exception:handle_uncaught_exception] [ERROR]- Internal Server Error: /api/api_list/1/
Traceback (most recent call last):
  File "C:\Users\huqiang\AppData\Local\Programs\Python\Python36\lib\site-packages\django\core\handlers\exception.py", line 35, in inner
    response = get_response(request)
  File "C:\Users\huqiang\AppData\Local\Programs\Python\Python36\lib\site-packages\django\core\handlers\base.py", line 128, in _get_response
    response = self.process_exception_by_middleware(e, request)
  File "C:\Users\huqiang\AppData\Local\Programs\Python\Python36\lib\site-packages\django\core\handlers\base.py", line 126, in _get_response
    response = wrapped_callback(request, *callback_args, **callback_kwargs)
  File "D:/HttpRunnerManager\HttpRunnerManager\activator.py", line 15, in process
    result = fun(request, index) if index else fun(request)
  File "D:/HttpRunnerManager\ApiManager\views.py", line 39, in wrapper
    return func(request, *args, **kwargs)
  File "D:/HttpRunnerManager\ApiManager\views.py", line 433, in api_list
    return render_to_response('api_list.html', manage_info)
  File "C:\Users\huqiang\AppData\Local\Programs\Python\Python36\lib\site-packages\django\shortcuts.py", line 27, in render_to_response
    content = loader.render_to_string(template_name, context, using=using)
  File "C:\Users\huqiang\AppData\Local\Programs\Python\Python36\lib\site-packages\django\template\loader.py", line 62, in render_to_string
    return template.render(context, request)
  File "C:\Users\huqiang\AppData\Local\Programs\Python\Python36\lib\site-packages\django\template\backends\django.py", line 61, in render
    return self.template.render(context)
  File "C:\Users\huqiang\AppData\Local\Programs\Python\Python36\lib\site-packages\django\template\base.py", line 175, in render
    return self._render(context)
  File "C:\Users\huqiang\AppData\Local\Programs\Python\Python36\lib\site-packages\django\template\base.py", line 167, in _render
    return self.nodelist.render(context)
  File "C:\Users\huqiang\AppData\Local\Programs\Python\Python36\lib\site-packages\django\template\base.py", line 943, in render
    bit = node.render_annotated(context)
  File "C:\Users\huqiang\AppData\Local\Programs\Python\Python36\lib\site-packages\django\template\base.py", line 910, in render_annotated
    return self.render(context)
  File "C:\Users\huqiang\AppData\Local\Programs\Python\Python36\lib\site-packages\django\template\loader_tags.py", line 155, in render
    return compiled_parent._render(context)
  File "C:\Users\huqiang\AppData\Local\Programs\Python\Python36\lib\site-packages\django\template\base.py", line 167, in _render
    return self.nodelist.render(context)
  File "C:\Users\huqiang\AppData\Local\Programs\Python\Python36\lib\site-packages\django\template\base.py", line 943, in render
    bit = node.render_annotated(context)
  File "C:\Users\huqiang\AppData\Local\Programs\Python\Python36\lib\site-packages\django\template\base.py", line 910, in render_annotated
    return self.render(context)
  File "C:\Users\huqiang\AppData\Local\Programs\Python\Python36\lib\site-packages\django\template\loader_tags.py", line 67, in render
    result = block.nodelist.render(context)
  File "C:\Users\huqiang\AppData\Local\Programs\Python\Python36\lib\site-packages\django\template\base.py", line 943, in render
    bit = node.render_annotated(context)
  File "C:\Users\huqiang\AppData\Local\Programs\Python\Python36\lib\site-packages\django\template\base.py", line 910, in render_annotated
    return self.render(context)
  File "C:\Users\huqiang\AppData\Local\Programs\Python\Python36\lib\site-packages\django\template\defaulttags.py", line 211, in render
    nodelist.append(node.render_annotated(context))
  File "C:\Users\huqiang\AppData\Local\Programs\Python\Python36\lib\site-packages\django\template\base.py", line 910, in render_annotated
    return self.render(context)
  File "C:\Users\huqiang\AppData\Local\Programs\Python\Python36\lib\site-packages\django\template\defaulttags.py", line 161, in render
    values = self.sequence.resolve(context, True)
  File "C:\Users\huqiang\AppData\Local\Programs\Python\Python36\lib\site-packages\django\template\base.py", line 703, in resolve
    new_obj = func(obj, *arg_vals)
  File "D:/HttpRunnerManager\ApiManager\templatetags\custom_tags.py", line 27, in convert_eval
    return update_include(eval(value))
TypeError: eval() arg 1 must be a string, bytes or code object
2020-01-20 16:47:44,665 [django.request:118] [exception:handle_uncaught_exception] [ERROR]- Internal Server Error: /api/add_api/
Traceback (most recent call last):
  File "C:\Users\huqiang\AppData\Local\Programs\Python\Python36\lib\site-packages\django\core\handlers\exception.py", line 35, in inner
    response = get_response(request)
  File "C:\Users\huqiang\AppData\Local\Programs\Python\Python36\lib\site-packages\django\core\handlers\base.py", line 128, in _get_response
    response = self.process_exception_by_middleware(e, request)
  File "C:\Users\huqiang\AppData\Local\Programs\Python\Python36\lib\site-packages\django\core\handlers\base.py", line 126, in _get_response
    response = wrapped_callback(request, *callback_args, **callback_kwargs)
  File "D:/HttpRunnerManager\HttpRunnerManager\activator.py", line 15, in process
    result = fun(request, index) if index else fun(request)
  File "D:/HttpRunnerManager\ApiManager\views.py", line 39, in wrapper
    return func(request, *args, **kwargs)
  File "D:/HttpRunnerManager\ApiManager\views.py", line 194, in add_api
    msg = api_info_logic(**testcase_info)
  File "D:/HttpRunnerManager\ApiManager\utils\common.py", line 408, in api_info_logic
    return add_api_data(type, **kwargs)
  File "D:/HttpRunnerManager\ApiManager\utils\operation.py", line 191, in add_api_data
    if api_opt.get_api_name(name, module, project) < 1:
  File "D:/HttpRunnerManager\ApiManager\managers.py", line 176, in get_api_name
    return self.filter(belong_module__id=module_name).filter(Api_name__exact=name).filter(
  File "C:\Users\huqiang\AppData\Local\Programs\Python\Python36\lib\site-packages\django\db\models\query.py", line 836, in filter
    return self._filter_or_exclude(False, *args, **kwargs)
  File "C:\Users\huqiang\AppData\Local\Programs\Python\Python36\lib\site-packages\django\db\models\query.py", line 854, in _filter_or_exclude
    clone.query.add_q(Q(*args, **kwargs))
  File "C:\Users\huqiang\AppData\Local\Programs\Python\Python36\lib\site-packages\django\db\models\sql\query.py", line 1253, in add_q
    clause, _ = self._add_q(q_object, self.used_aliases)
  File "C:\Users\huqiang\AppData\Local\Programs\Python\Python36\lib\site-packages\django\db\models\sql\query.py", line 1277, in _add_q
    split_subq=split_subq,
  File "C:\Users\huqiang\AppData\Local\Programs\Python\Python36\lib\site-packages\django\db\models\sql\query.py", line 1153, in build_filter
    lookups, parts, reffed_expression = self.solve_lookup_type(arg)
  File "C:\Users\huqiang\AppData\Local\Programs\Python\Python36\lib\site-packages\django\db\models\sql\query.py", line 1015, in solve_lookup_type
    _, field, _, lookup_parts = self.names_to_path(lookup_splitted, self.get_meta())
  File "C:\Users\huqiang\AppData\Local\Programs\Python\Python36\lib\site-packages\django\db\models\sql\query.py", line 1379, in names_to_path
    "Choices are: %s" % (name, ", ".join(available)))
django.core.exceptions.FieldError: Cannot resolve keyword 'Api_name' into field. Choices are: author, belong_module, belong_module_id, belong_project, create_time, id, include, name, request, type, update_time
2020-01-20 16:52:40,336 [HttpRunnerManager:193] [operation:add_api_data] [INFO]- 888888888888接口添加成功: {'test': {'request': {'url': '888888', 'method': 'POST', 'data': {'8888888888': '888888888888'}}, 'name': '888888888888'}}
2020-01-20 16:52:49,137 [django.request:118] [exception:handle_uncaught_exception] [ERROR]- Internal Server Error: /api/edit_case/2/
Traceback (most recent call last):
  File "C:\Users\huqiang\AppData\Local\Programs\Python\Python36\lib\site-packages\django\core\handlers\exception.py", line 35, in inner
    response = get_response(request)
  File "C:\Users\huqiang\AppData\Local\Programs\Python\Python36\lib\site-packages\django\core\handlers\base.py", line 128, in _get_response
    response = self.process_exception_by_middleware(e, request)
  File "C:\Users\huqiang\AppData\Local\Programs\Python\Python36\lib\site-packages\django\core\handlers\base.py", line 126, in _get_response
    response = wrapped_callback(request, *callback_args, **callback_kwargs)
  File "D:/HttpRunnerManager\HttpRunnerManager\activator.py", line 15, in process
    result = fun(request, index) if index else fun(request)
  File "D:/HttpRunnerManager\ApiManager\views.py", line 39, in wrapper
    return func(request, *args, **kwargs)
  File "D:/HttpRunnerManager\ApiManager\views.py", line 482, in edit_case
    request = eval(test_info[0].request)
  File "C:\Users\huqiang\AppData\Local\Programs\Python\Python36\lib\site-packages\django\db\models\query.py", line 307, in __getitem__
    return qs._result_cache[0]
IndexError: list index out of range
2020-01-20 16:54:05,436 [django.request:118] [exception:handle_uncaught_exception] [ERROR]- Internal Server Error: /api/edit_case/3/
Traceback (most recent call last):
  File "C:\Users\huqiang\AppData\Local\Programs\Python\Python36\lib\site-packages\django\core\handlers\exception.py", line 35, in inner
    response = get_response(request)
  File "C:\Users\huqiang\AppData\Local\Programs\Python\Python36\lib\site-packages\django\core\handlers\base.py", line 128, in _get_response
    response = self.process_exception_by_middleware(e, request)
  File "C:\Users\huqiang\AppData\Local\Programs\Python\Python36\lib\site-packages\django\core\handlers\base.py", line 126, in _get_response
    response = wrapped_callback(request, *callback_args, **callback_kwargs)
  File "D:/HttpRunnerManager\HttpRunnerManager\activator.py", line 15, in process
    result = fun(request, index) if index else fun(request)
  File "D:/HttpRunnerManager\ApiManager\views.py", line 39, in wrapper
    return func(request, *args, **kwargs)
  File "D:/HttpRunnerManager\ApiManager\views.py", line 482, in edit_case
    request = eval(test_info[0].request)
  File "C:\Users\huqiang\AppData\Local\Programs\Python\Python36\lib\site-packages\django\db\models\query.py", line 307, in __getitem__
    return qs._result_cache[0]
IndexError: list index out of range
2020-01-20 16:55:42,861 [django.request:118] [exception:handle_uncaught_exception] [ERROR]- Internal Server Error: /api/test_list/1/
Traceback (most recent call last):
  File "C:\Users\huqiang\AppData\Local\Programs\Python\Python36\lib\site-packages\django\core\handlers\exception.py", line 35, in inner
    response = get_response(request)
  File "C:\Users\huqiang\AppData\Local\Programs\Python\Python36\lib\site-packages\django\core\handlers\base.py", line 128, in _get_response
    response = self.process_exception_by_middleware(e, request)
  File "C:\Users\huqiang\AppData\Local\Programs\Python\Python36\lib\site-packages\django\core\handlers\base.py", line 126, in _get_response
    response = wrapped_callback(request, *callback_args, **callback_kwargs)
  File "D:/HttpRunnerManager\HttpRunnerManager\activator.py", line 15, in process
    result = fun(request, index) if index else fun(request)
  File "D:/HttpRunnerManager\ApiManager\views.py", line 39, in wrapper
    return func(request, *args, **kwargs)
  File "D:/HttpRunnerManager\ApiManager\views.py", line 384, in test_list
    msg = copy_test_data(test_info.get('data').pop('index'), test_info.get('data').pop('name'))
TypeError: copy_test_data() missing 1 required positional argument: 'tag'
2020-01-20 17:09:34,030 [django.request:118] [exception:handle_uncaught_exception] [ERROR]- Internal Server Error: /api/test_list/1/
Traceback (most recent call last):
TypeError: del_test_data() missing 1 required positional argument: 'tag'
2020-01-20 17:19:20,079 [django.request:118] [exception:handle_uncaught_exception] [ERROR]- Internal Server Error: /api/test_list/1/
Traceback (most recent call last):
TypeError: del_test_data() missing 1 required positional argument: 'tag'
2020-01-20 17:19:44,912 [django.request:118] [exception:handle_uncaught_exception] [ERROR]- Internal Server Error: /api/test_list/1/
Traceback (most recent call last):
TypeError: del_test_data() missing 1 required positional argument: 'tag'
2020-01-20 17:26:00,997 [HttpRunnerManager:193] [operation:add_api_data] [INFO]- 99999999999999接口添加成功: {'test': {'request': {'url': '888888889', 'method': 'POST', 'data': {'9999999999': '999999999999999999999'}}, 'name': '99999999999999'}}
2020-01-20 17:29:15,042 [django.request:118] [exception:handle_uncaught_exception] [ERROR]- Internal Server Error: /api/test_list/1/
Traceback (most recent call last):
TypeError: copy_test_data() missing 1 required positional argument: 'tag'
2020-01-20 17:29:53,246 [django.request:118] [exception:handle_uncaught_exception] [ERROR]- Internal Server Error: /api/test_list/1/
Traceback (most recent call last):
TypeError: copy_test_data() missing 1 required positional argument: 'tag'
2020-01-20 17:30:17,969 [django.request:118] [exception:handle_uncaught_exception] [ERROR]- Internal Server Error: /api/test_list/1/
Traceback (most recent call last):
TypeError: copy_test_data() missing 1 required positional argument: 'tag'
2020-01-20 17:30:45,613 [django.request:118] [exception:handle_uncaught_exception] [ERROR]- Internal Server Error: /api/test_list/1/
Traceback (most recent call last):
TypeError: copy_test_data() missing 1 required positional argument: 'tag'
2020-01-20 17:31:55,164 [django.request:118] [exception:handle_uncaught_exception] [ERROR]- Internal Server Error: /api/test_list/1/
Traceback (most recent call last):
TypeError: copy_test_data() missing 1 required positional argument: 'tag'
2020-01-20 17:44:23,799 [django.request:118] [exception:handle_uncaught_exception] [ERROR]- Internal Server Error: /api/upload_file/
Traceback (most recent call last):
AttributeError: 'str' object has no attribute 'keys'
